Workbook

Sheet RAW_DATA
A1: Record_ID | B1: Full_Name | C1: Email | D1: Phone | E1: Company | F1: Country | G1: Lead_Source | H1: Service_Interest | I1: Lead_Status | J1: Estimated_Value_USD | K1: Created_Date | L1: Last_Contact_Date | M1: Notes
A2: ALM-0001 | B2: Alejandro Navarro | C2: alejandro.navarro94@company.com | D2: 201539268 | E2: Apex Studio | F2: CHILE | G2: Organic Search | H2: Document Processing | I2: Contacted | K2: 46111 | L2: 46153 | M2: Follow up next week
A3: ALM-0002 | B3: Valeria Rivera | C3: valeria.rivera98@outlook.com | D3: +1-5585000486 | E3: Green Studio | F3: United States | G3: Website | H3: Workflow Automation | I3: New | J3: 1200 | K3: 46263 | L3: 46304 | M3: Needs pricing
A4: ALM-0003 | B4: Carlos Navarro | C4: carlos.navarro11@mail.com | D4: +503 23813586 | E4: Momentum Services | F4: El Salvador | G4: Referral | H4: AI Voice Agent | I4: New | J4: 500 | K4: 46101
A5: ALM-0004 | B5: María González | C5: maria.gonzalez3@outlook.com | D5: +54 8433709892 | E5: Sol Partners | F5: ARGENTINA | G5: Website | H5: AI Voice Agent | I5: Lost | J5: 1500 | K5: 46215 | L5: 46244 | M5: Follow up next week
A6: ALM-0005 | B6: Carolina Navarro | C6: carolina.navarro41@gmail.com | D6: +51 696 199 746 | E6: Bright Partners | F6: peru | G6: Referral | H6: AI Voice Agent | I6: Won | J6: 350 | K6: 46174 | L6: 46191 | M6: Interested in automation
A7: ALM-0006 | B7: Paula Díaz | C7: paula.diaz25@outlook.com | D7: +56 510972174 | E7: Digital Studio | F7: chile | G7: Facebook | H7: AI Voice Agent | I7: Won | J7: 500 | K7: 46245 | L7: 46255 | M7: Follow up next week
A8: ALM-0007 | B8: María Rivera | C8: maria.rivera61@outlook.com | D8: +1 2474157676 | E8: CLOUD SOLUTIONS | F8: U.S.A. | G8: Instagram | H8: Data Automation | I8: Proposal Sent | J8: 500 | K8: 46052 | L8: 46087 | M8: Requested demo
A9: ALM-0008 | B9: PATRICIA MARTÍNEZ | C9: patricia.martinez26@gmail.com | D9: +503 09369254 | E9: Vision Solutions | F9: El Salvador | G9: Website | H9: Document Processing | I9: Contacted | J9: 1200 | K9: 46232 | L9: 46254
A10: ALM-0009 | B10: Miguel Rodríguez | C10: miguel.rodriguez72@outlook.com | D10: +503 70533950 | E10: Nova Commerce | F10: el salvador | G10: Organic Search | H10: Document Processing | I10: Contacted | J10: 1500 | K10: 46095 | L10: 46129 | M10: Requested demo
A11: ALM-0010 | B11: Manuel López | C11: manuel.lopez9@outlook.com | D11: 2859040010 | E11: Momentum Studio | F11: ARGENTINA | G11: Website | H11: Data Automation | I11: Proposal Sent | J11: 350 | K11: 46180 | L11: 46181 | M11: Needs pricing
A12: ALM-0011 | B12: Patricia Pérez | C12: patricia.perez5@outlook.com | D12: +34-105504239 | E12: Nexo Group | F12: spain | G12: Website | H12: Workflow Automation | I12: Proposal Sent | J12: 1200 | K12: 46160 | M12: Interested in automation
A13: ALM-0012 | B13: Andrés Martínez | C13: andres.martinez22@mail.com | D13: +54-2437252546 | E13: Apex Services | F13: ARGENTINA | G13: LinkedIn | H13: Document Processing | I13: Lost | J13: 900 | K13: 46179 | L13: 46199 | M13: Send proposal
A14: ALM-0013 | B14: natalia ortiz | C14: natalia.ortiz66@gmail.com | D14: +54-2332522808 | E14: Sol Solutions | F14: ARGENTINA | G14: LinkedIn | H14: Data Automation | I14: Won | J14: 350 | K14: 46051 | L14: 46051 | M14: Send proposal
A15: ALM-0014 | B15: Camila Torres | C15: camila.torres47@company.com | F15: spain | G15: Website | H15: Workflow Automation | I15: Proposal Sent | J15: 1500 | K15: 46030 | L15: 46043 | M15: Follow up next week
A16: ALM-0015 | B16: Sergio Ortiz | C16: sergio.ortiz49@company.com | D16: +1-8301135501 | E16: Vision Partners | F16: United States | G16: Website | H16: Document Processing | I16: New | J16: 2500 | K16: 46070 | L16: 46081 | M16: Requested demo
A17: ALM-0016 | B17: Javier Díaz | C17: javier.diaz69@gmail.com | D17: 425439667 | E17: Nova Partners | F17: PERU | G17: Organic Search | H17: Document Processing | I17: Lost | J17: 350 | K17: 46137 | L17: 46175 | M17: Follow up next week
A18: ALM-0017 | B18: Javier Martínez | C18: javier.martinez59@mail.com | D18: 2133177044 | E18: Apex Solutions | F18: Argentina | G18: Facebook | H18: Document Processing | I18: Qualified | J18: 2000 | K18: 46045 | L18: 46079 | M18: Requested demo
A19: ALM-0018 | B19: Isabel Gómez | C19: isabel.gomez32@mail.com | D19: 825136069 | E19: Apex Consulting | F19: Perú | G19: Website | H19: Document Processing | I19: Lost | J19: 4500 | K19: 46245 | L19: 46255 | M19: Send proposal
A20: ALM-0019 | B20: Luis Rodríguez | C20: luis.rodriguez98@gmail.com | D20: +51 380 353 771 | E20: Atlas Consulting | F20: PERU | G20: Referral | H20: Data Automation | I20: New | J20: 3000 | K20: 46037 | L20: 46053 | M20: Needs pricing
A21: ALM-0020 | B21: Natalia Díaz | C21: natalia.diaz38@mail.com | D21: +503 574 493 38 | E21: Prime Group | F21: EL SALVADOR | G21: Referral | H21: Document Processing | I21: Contacted | J21: 1200 | K21: 46231 | L21: 46231
A22: ALM-0021 | B22: Daniel Flores | C22: daniel.flores94@outlook.com | D22: 61320024 | E22: Urban Commerce | F22: El Salvador | G22: Instagram | H22: Data Automation | I22: New | J22: 500 | K22: 46232 | L22: 46263 | M22: Needs pricing
A23: ALM-0022 | B23: Sergio Gómez | C23: sergio.gomez90@outlook.com | D23: 3145091327 | E23: Sol Commerce | F23: argentina | G23: Facebook | H23: Document Processing | I23: Won | J23: 2500 | K23: 46209 | L23: 46233
A24: ALM-0023 | B24: Raúl Hernández | C24: raul.hernandez69@company.com | D24: 1239353409 | E24: Vertex Solutions | F24: argentina | G24: Organic Search | H24: AI Voice Agent | I24: Contacted | J24: 750 | K24: 46149 | L24: 46157 | M24: Interested in automation
A25: ALM-0024 | B25: Sergio Hernández | C25: sergio.hernandez12@outlook.com | D25: +57 299 254 3784 | E25: Sol Commerce | F25: colombia | G25: Website | H25: Data Automation | I25: Won | J25: 2500 | K25: 46033 | L25: 46069 | M25: Interested in automation
A26: ALM-0025 | B26: Paula Díaz | C26: paula.diaz76@mail.com | E26: MOMENTUM SERVICES | F26: Peru | G26: Referral | H26: Workflow Automation | I26: Qualified | J26: 4500 | K26: 46032 | L26: 46068
A27: ALM-0026 | B27: Diego García | C27: diego.garcia78@gmail.com | D27: 2309827434 | E27: Vision Services | F27: ARGENTINA | G27: Organic Search | H27: Workflow Automation | I27: New | J27: 1500 | K27: 46253 | L27: 46286 | M27: Requested demo
A28: ALM-0027 | B28: Daniel Pérez | C28: daniel.perez13 @ gmail.com | E28: Bright Solutions | F28: argentina | G28: Instagram | H28: Data Automation | I28: Won | J28: 350 | K28: 46121 | L28: 46153 | M28: Send proposal
A29: ALM-0028 | B29: Fernando Morales | C29: fernando.morales39@company.com | D29: +54 5898158879 | E29: Prime Labs | F29: ARGENTINA | G29: Website | H29: AI Voice Agent | I29: Won | J29: 4500 | K29: 46206 | L29: 46206 | M29: Interested in automation
A30: ALM-0029 | B30: Alejandro Torres | C30: alejandro.torres56@company.com | D30: +52 0203959259 | E30: Cloud Commerce | F30: Mexico | G30: Organic Search | H30: AI Voice Agent | I30: Qualified | J30: 3000 | K30: 46103 | L30: 46112
A31: ALM-0030 | B31: Alejandro Ramírez | C31: alejandro.ramirez44@company.com | F31: chile | G31: Facebook | H31: Data Automation | I31: New | J31: 2500 | K31: 46134 | L31: 46169 | M31: Interested in automation
A32: ALM-0031 | B32: Raúl Rodríguez | C32: raul.rodriguez57@gmail.com | D32: +52-8554682838 | E32: Blue Studio | F32: México | G32: Facebook | H32: Document Processing | I32: Proposal Sent | J32: 750 | K32: 46183 | L32: 46216
A33: ALM-0032 | B33: Diego Navarro | C33: diego.navarro64@mail.com | E33: Blue Services | F33: Salvador | G33: Organic Search | H33: Website Chat Agent | I33: New | K33: 46095 | L33: 46099 | M33: Interested in automation
A34: ALM-0033 | B34: Andrés Sánchez | C34: andres.sanchez74@outlook.com | D34: +1-4772755215 | E34: Urban Works | F34: United States | G34: Organic Search | H34: Website Chat Agent | I34: Won | J34: 750 | K34: 46190 | L34: 46192 | M34: Requested demo
A35: ALM-0034 | B35: Manuel Morales | C35: manuel.morales27@gmail.com | D35: 881839487 | E35: Sol Labs | F35: peru | G35: Website | H35: AI Voice Agent | I35: Won | J35: 3000 | K35: 46030 | L35: 46052 | M35: Follow up next week
A36: ALM-0035 | B36: Alejandro Sánchez | C36: alejandro.sanchez42@mail.com | D36: +57 406 830 4098 | E36: Apex Services | F36: colombia | G36: Instagram | H36: Data Automation | I36: Lost | J36: 500 | K36: 46092 | L36: 46135
A37: ALM-0036 | B37: Patricia Díaz | C37: patricia.diaz43@company.com | D37: +503 323 170 50 | E37: Vertex Labs | F37: El Salvador | G37: Organic Search | H37: Website Chat Agent | I37: Proposal Sent | J37: 4500 | K37: 46035 | L37: 46080 | M37: Needs pricing
A38: ALM-0037 | B38: David Torres | C38: david.torres10@company.com | D38: +56 625 147 716 | E38: Bright Commerce | F38: CHILE | G38: Referral | H38: Website Chat Agent | I38: Lost | J38: 3000 | K38: 46134 | L38: 46154 | M38: Requested demo
A39: ALM-0038 | B39: Fernando Romero | C39: fernando.romero63@gmail.com | D39: 5161885601 | E39: Apex Labs | F39: COLOMBIA | G39: LinkedIn | H39: Data Automation | I39: Proposal Sent | J39: 350 | K39: 46153 | L39: 46161 | M39: Send proposal
A40: ALM-0039 | B40: Fernando Rivera | C40: fernando.rivera80@company.com | D40: +57 1778362014 | F40: colombia | G40: Instagram | H40: Workflow Automation | I40: Won | J40: 350 | K40: 46090 | L40: 46090 | M40: Interested in automation
...

Sheet CLEAN_DATA
A1: Record_ID | B1: Full_Name | C1: Email | D1: Email_Normalized | E1: Email_Action | F1: Email_Clean | G1: Duplicate_Status | H1: Data_Action | I1: Email_Quality | J1: Phone | K1: Company | L1: Country | M1: Country_Normalized | N1: Lead_Source | O1: Service_Interest | P1: Lead_Status | Q1: Lead_Status_Normalized | R1: Estimated_Value_USD | S1: Created_Date | T1: Last_Contact_Date | U1: Notes
A2: ALM-0001 | B2: Alejandro Navarro | C2: alejandro.navarro94@company.com | D2: =LOWER(TRIM(C2)) -> alejandro.navarro94@company.com | G2: =IF(D2="","Missing Email",IF(COUNTIF($D$2:$D$201,D2)>1,"Duplicate","Unique")) -> Unique | I2: =IFERROR(__xludf.DUMMYFUNCTION("IF(C2="""",""Missing"",IF(REGEXMATCH(C2,""^[^@\s]+@[^@\s]+\.[^@\s]+$""),""Valid"",""Invalid""))"),"Valid") -> Valid | J2: 201539268 | K2: Apex Studio | L2: CHILE | M2: =IF(L2="","",IF(OR(LOWER(TRIM(L2))="u.s.a.",LOWER(TRIM(L2))="united states"),"United States",IF(OR(LOWER(TRIM(L2))="spain",LOWER(TRIM(L2))="españa",LOWER(TRIM(L2))="espana"),"Spain",IF(OR(LOWER(TRIM(L2))="mexico",LOWER(TRIM(L2))="méxico"),"Mexico",PROPER(LOWER(TRIM(L2))))))) -> Chile | N2: Organic Search | O2: Document Processing | P2: Contacted | Q2: =IF(P2="","",PROPER(LOWER(TRIM(P2)))) -> Contacted | S2: 46111 | T2: 46153 | U2: Follow up next week | V2: Duplicados por email
A3: ALM-0072 | B3: Camila González | C3: camila.gonzalez86@mail.com | D3: =LOWER(TRIM(C3)) -> camila.gonzalez86@mail.com | G3: =IF(D3="","Missing Email",IF(COUNTIF($D$2:$D$201,D3)>1,"Duplicate","Unique")) -> Duplicate | I3: =IFERROR(__xludf.DUMMYFUNCTION("IF(C3="""",""Missing"",IF(REGEXMATCH(C3,""^[^@\s]+@[^@\s]+\.[^@\s]+$""),""Valid"",""Invalid""))"),"Valid") -> Valid | J3: +56-124965231 | K3: Digital Labs | L3: Chile | M3: =IF(L3="","",IF(OR(LOWER(TRIM(L3))="u.s.a.",LOWER(TRIM(L3))="united states"),"United States",IF(OR(LOWER(TRIM(L3))="spain",LOWER(TRIM(L3))="españa",LOWER(TRIM(L3))="espana"),"Spain",IF(OR(LOWER(TRIM(L3))="mexico",LOWER(TRIM(L3))="méxico"),"Mexico",PROPER(LOWER(TRIM(L3))))))) -> Chile | N3: Instagram | O3: Workflow Automation | P3: Contacted | Q3: =IF(P3="","",PROPER(LOWER(TRIM(P3)))) -> Contacted | R3: 3000 | S3: 46088 | T3: 46113 | U3: Requested demo
A4: ALM-0003 | B4: Carlos Navarro | C4: carlos.navarro11@mail.com | D4: =LOWER(TRIM(C4)) -> carlos.navarro11@mail.com | G4: =IF(D4="","Missing Email",IF(COUNTIF($D$2:$D$201,D4)>1,"Duplicate","Unique")) -> Unique | I4: =IFERROR(__xludf.DUMMYFUNCTION("IF(C4="""",""Missing"",IF(REGEXMATCH(C4,""^[^@\s]+@[^@\s]+\.[^@\s]+$""),""Valid"",""Invalid""))"),"Valid") -> Valid | J4: +503 23813586 | K4: Momentum Services | L4: El Salvador | M4: =IF(L4="","",IF(OR(LOWER(TRIM(L4))="u.s.a.",LOWER(TRIM(L4))="united states"),"United States",IF(OR(LOWER(TRIM(L4))="spain",LOWER(TRIM(L4))="españa",LOWER(TRIM(L4))="espana"),"Spain",IF(OR(LOWER(TRIM(L4))="mexico",LOWER(TRIM(L4))="méxico"),"Mexico",PROPER(LOWER(TRIM(L4))))))) -> El Salvador | N4: Referral | O4: AI Voice Agent | P4: New | Q4: =IF(P4="","",PROPER(LOWER(TRIM(P4)))) -> New | R4: 500 | S4: 46101
A5: ALM-0004 | B5: María González | C5: maria.gonzalez3@outlook.com | D5: =LOWER(TRIM(C5)) -> maria.gonzalez3@outlook.com | G5: =IF(D5="","Missing Email",IF(COUNTIF($D$2:$D$201,D5)>1,"Duplicate","Unique")) -> Unique | I5: =IFERROR(__xludf.DUMMYFUNCTION("IF(C5="""",""Missing"",IF(REGEXMATCH(C5,""^[^@\s]+@[^@\s]+\.[^@\s]+$""),""Valid"",""Invalid""))"),"Valid") -> Valid | J5: +54 8433709892 | K5: Sol Partners | L5: ARGENTINA | M5: =IF(L5="","",IF(OR(LOWER(TRIM(L5))="u.s.a.",LOWER(TRIM(L5))="united states"),"United States",IF(OR(LOWER(TRIM(L5))="spain",LOWER(TRIM(L5))="españa",LOWER(TRIM(L5))="espana"),"Spain",IF(OR(LOWER(TRIM(L5))="mexico",LOWER(TRIM(L5))="méxico"),"Mexico",PROPER(LOWER(TRIM(L5))))))) -> Argentina | N5: Website | O5: AI Voice Agent | P5: Lost | Q5: =IF(P5="","",PROPER(LOWER(TRIM(P5)))) -> Lost | R5: 1500 | S5: 46215 | T5: 46244 | U5: Follow up next week
A6: ALM-0005 | B6: Carolina Navarro | C6: carolina.navarro41@gmail.com | D6: =LOWER(TRIM(C6)) -> carolina.navarro41@gmail.com | G6: =IF(D6="","Missing Email",IF(COUNTIF($D$2:$D$201,D6)>1,"Duplicate","Unique")) -> Unique | I6: =IFERROR(__xludf.DUMMYFUNCTION("IF(C6="""",""Missing"",IF(REGEXMATCH(C6,""^[^@\s]+@[^@\s]+\.[^@\s]+$""),""Valid"",""Invalid""))"),"Valid") -> Valid | J6: +51 696 199 746 | K6: Bright Partners | L6: peru | M6: =IF(L6="","",IF(OR(LOWER(TRIM(L6))="u.s.a.",LOWER(TRIM(L6))="united states"),"United States",IF(OR(LOWER(TRIM(L6))="spain",LOWER(TRIM(L6))="españa",LOWER(TRIM(L6))="espana"),"Spain",IF(OR(LOWER(TRIM(L6))="mexico",LOWER(TRIM(L6))="méxico"),"Mexico",PROPER(LOWER(TRIM(L6))))))) -> Peru | N6: Referral | O6: AI Voice Agent | P6: Won | Q6: =IF(P6="","",PROPER(LOWER(TRIM(P6)))) -> Won | R6: 350 | S6: 46174 | T6: 46191 | U6: Interested in automation | V6: Registros marcados Duplicate
A7: ALM-0191 | B7: Camila González | C7: camila.gonzalez86@mail.com | D7: =LOWER(TRIM(C7)) -> camila.gonzalez86@mail.com | G7: =IF(D7="","Missing Email",IF(COUNTIF($D$2:$D$201,D7)>1,"Duplicate","Unique")) -> Duplicate | H7: REMOVE — Exact duplicate of ALM-0014 | I7: =IFERROR(__xludf.DUMMYFUNCTION("IF(C7="""",""Missing"",IF(REGEXMATCH(C7,""^[^@\s]+@[^@\s]+\.[^@\s]+$""),""Valid"",""Invalid""))"),"Valid") -> Valid | J7: +56-124965231 | K7: Digital Labs | L7: Chile | M7: =IF(L7="","",IF(OR(LOWER(TRIM(L7))="u.s.a.",LOWER(TRIM(L7))="united states"),"United States",IF(OR(LOWER(TRIM(L7))="spain",LOWER(TRIM(L7))="españa",LOWER(TRIM(L7))="espana"),"Spain",IF(OR(LOWER(TRIM(L7))="mexico",LOWER(TRIM(L7))="méxico"),"Mexico",PROPER(LOWER(TRIM(L7))))))) -> Chile | N7: Instagram | O7: Workflow Automation | P7: Contacted | Q7: =IF(P7="","",PROPER(LOWER(TRIM(P7)))) -> Contacted | R7: 3000 | S7: 46088 | T7: 46113 | U7: Requested demo
A8: ALM-0007 | B8: María Rivera | C8: maria.rivera61@outlook.com | D8: =LOWER(TRIM(C8)) -> maria.rivera61@outlook.com | G8: =IF(D8="","Missing Email",IF(COUNTIF($D$2:$D$201,D8)>1,"Duplicate","Unique")) -> Unique | I8: =IFERROR(__xludf.DUMMYFUNCTION("IF(C8="""",""Missing"",IF(REGEXMATCH(C8,""^[^@\s]+@[^@\s]+\.[^@\s]+$""),""Valid"",""Invalid""))"),"Valid") -> Valid | J8: +1 2474157676 | K8: CLOUD SOLUTIONS | L8: U.S.A. | M8: =IF(L8="","",IF(OR(LOWER(TRIM(L8))="u.s.a.",LOWER(TRIM(L8))="united states"),"United States",IF(OR(LOWER(TRIM(L8))="spain",LOWER(TRIM(L8))="españa",LOWER(TRIM(L8))="espana"),"Spain",IF(OR(LOWER(TRIM(L8))="mexico",LOWER(TRIM(L8))="méxico"),"Mexico",PROPER(LOWER(TRIM(L8))))))) -> United States | N8: Instagram | O8: Data Automation | P8: Proposal Sent | Q8: =IF(P8="","",PROPER(LOWER(TRIM(P8)))) -> Proposal Sent | R8: 500 | S8: 46052 | T8: 46087 | U8: Requested demo | V8: Emails duplicados distintos
A9: ALM-0014 | B9: Camila Torres | C9: camila.torres47@company.com | D9: =LOWER(TRIM(C9)) -> camila.torres47@company.com | G9: =IF(D9="","Missing Email",IF(COUNTIF($D$2:$D$201,D9)>1,"Duplicate","Unique")) -> Duplicate | I9: =IFERROR(__xludf.DUMMYFUNCTION("IF(C9="""",""Missing"",IF(REGEXMATCH(C9,""^[^@\s]+@[^@\s]+\.[^@\s]+$""),""Valid"",""Invalid""))"),"Valid") -> Valid | L9: spain | M9: =IF(L9="","",IF(OR(LOWER(TRIM(L9))="u.s.a.",LOWER(TRIM(L9))="united states"),"United States",IF(OR(LOWER(TRIM(L9))="spain",LOWER(TRIM(L9))="españa",LOWER(TRIM(L9))="espana"),"Spain",IF(OR(LOWER(TRIM(L9))="mexico",LOWER(TRIM(L9))="méxico"),"Mexico",PROPER(LOWER(TRIM(L9))))))) -> Spain | N9: Website | O9: Workflow Automation | P9: Proposal Sent | Q9: =IF(P9="","",PROPER(LOWER(TRIM(P9)))) -> Proposal Sent | R9: 1500 | S9: 46030 | T9: 46043 | U9: Follow up next week
A10: ALM-0009 | B10: Miguel Rodríguez | C10: miguel.rodriguez72@outlook.com | D10: =LOWER(TRIM(C10)) -> miguel.rodriguez72@outlook.com | G10: =IF(D10="","Missing Email",IF(COUNTIF($D$2:$D$201,D10)>1,"Duplicate","Unique")) -> Unique | I10: =IFERROR(__xludf.DUMMYFUNCTION("IF(C10="""",""Missing"",IF(REGEXMATCH(C10,""^[^@\s]+@[^@\s]+\.[^@\s]+$""),""Valid"",""Invalid""))"),"Valid") -> Valid | J10: +503 70533950 | K10: Nova Commerce | L10: el salvador | M10: =IF(L10="","",IF(OR(LOWER(TRIM(L10))="u.s.a.",LOWER(TRIM(L10))="united states"),"United States",IF(OR(LOWER(TRIM(L10))="spain",LOWER(TRIM(L10))="españa",LOWER(TRIM(L10))="espana"),"Spain",IF(OR(LOWER(TRIM(L10))="mexico",LOWER(TRIM(L10))="méxico"),"Mexico",PROPER(LOWER(TRIM(L10))))))) -> El Salvador | N10: Organic Search | O10: Document Processing | P10: Contacted | Q10: =IF(P10="","",PROPER(LOWER(TRIM(P10)))) -> Contacted | R10: 1500 | S10: 46095 | T10: 46129 | U10: Requested demo | V10: Registros para eliminar
A11: ALM-0010 | B11: Manuel López | C11: manuel.lopez9@outlook.com | D11: =LOWER(TRIM(C11)) -> manuel.lopez9@outlook.com | G11: =IF(D11="","Missing Email",IF(COUNTIF($D$2:$D$201,D11)>1,"Duplicate","Unique")) -> Unique | I11: =IFERROR(__xludf.DUMMYFUNCTION("IF(C11="""",""Missing"",IF(REGEXMATCH(C11,""^[^@\s]+@[^@\s]+\.[^@\s]+$""),""Valid"",""Invalid""))"),"Valid") -> Valid | J11: 2859040010 | K11: Momentum Studio | L11: ARGENTINA | M11: =IF(L11="","",IF(OR(LOWER(TRIM(L11))="u.s.a.",LOWER(TRIM(L11))="united states"),"United States",IF(OR(LOWER(TRIM(L11))="spain",LOWER(TRIM(L11))="españa",LOWER(TRIM(L11))="espana"),"Spain",IF(OR(LOWER(TRIM(L11))="mexico",LOWER(TRIM(L11))="méxico"),"Mexico",PROPER(LOWER(TRIM(L11))))))) -> Argentina | N11: Website | O11: Data Automation | P11: Proposal Sent | Q11: =IF(P11="","",PROPER(LOWER(TRIM(P11)))) -> Proposal Sent | R11: 350 | S11: 46180 | T11: 46181 | U11: Needs pricing | V11: =COUNTIF(H2:H201,"REMOVE*") -> 9
A12: ALM-0011 | B12: Patricia Pérez | C12: patricia.perez5@outlook.com | D12: =LOWER(TRIM(C12)) -> patricia.perez5@outlook.com | G12: =IF(D12="","Missing Email",IF(COUNTIF($D$2:$D$201,D12)>1,"Duplicate","Unique")) -> Unique | I12: =IFERROR(__xludf.DUMMYFUNCTION("IF(C12="""",""Missing"",IF(REGEXMATCH(C12,""^[^@\s]+@[^@\s]+\.[^@\s]+$""),""Valid"",""Invalid""))"),"Valid") -> Valid | J12: +34-105504239 | K12: Nexo Group | L12: spain | M12: =IF(L12="","",IF(OR(LOWER(TRIM(L12))="u.s.a.",LOWER(TRIM(L12))="united states"),"United States",IF(OR(LOWER(TRIM(L12))="spain",LOWER(TRIM(L12))="españa",LOWER(TRIM(L12))="espana"),"Spain",IF(OR(LOWER(TRIM(L12))="mexico",LOWER(TRIM(L12))="méxico"),"Mexico",PROPER(LOWER(TRIM(L12))))))) -> Spain | N12: Website | O12: Workflow Automation | P12: Proposal Sent | Q12: =IF(P12="","",PROPER(LOWER(TRIM(P12)))) -> Proposal Sent | R12: 1200 | S12: 46160 | U12: Interested in automation
A13: ALM-0012 | B13: Andrés Martínez | C13: andres.martinez22@mail.com | D13: =LOWER(TRIM(C13)) -> andres.martinez22@mail.com | G13: =IF(D13="","Missing Email",IF(COUNTIF($D$2:$D$201,D13)>1,"Duplicate","Unique")) -> Unique | I13: =IFERROR(__xludf.DUMMYFUNCTION("IF(C13="""",""Missing"",IF(REGEXMATCH(C13,""^[^@\s]+@[^@\s]+\.[^@\s]+$""),""Valid"",""Invalid""))"),"Valid") -> Valid | J13: +54-2437252546 | K13: Apex Services | L13: ARGENTINA | M13: =IF(L13="","",IF(OR(LOWER(TRIM(L13))="u.s.a.",LOWER(TRIM(L13))="united states"),"United States",IF(OR(LOWER(TRIM(L13))="spain",LOWER(TRIM(L13))="españa",LOWER(TRIM(L13))="espana"),"Spain",IF(OR(LOWER(TRIM(L13))="mexico",LOWER(TRIM(L13))="méxico"),"Mexico",PROPER(LOWER(TRIM(L13))))))) -> Argentina | N13: LinkedIn | O13: Document Processing | P13: Lost | Q13: =IF(P13="","",PROPER(LOWER(TRIM(P13)))) -> Lost | R13: 900 | S13: 46179 | T13: 46199 | U13: Send proposal
A14: ALM-0013 | B14: natalia ortiz | C14: natalia.ortiz66@gmail.com | D14: =LOWER(TRIM(C14)) -> natalia.ortiz66@gmail.com | G14: =IF(D14="","Missing Email",IF(COUNTIF($D$2:$D$201,D14)>1,"Duplicate","Unique")) -> Unique | I14: =IFERROR(__xludf.DUMMYFUNCTION("IF(C14="""",""Missing"",IF(REGEXMATCH(C14,""^[^@\s]+@[^@\s]+\.[^@\s]+$""),""Valid"",""Invalid""))"),"Valid") -> Valid | J14: +54-2332522808 | K14: Sol Solutions | L14: ARGENTINA | M14: =IF(L14="","",IF(OR(LOWER(TRIM(L14))="u.s.a.",LOWER(TRIM(L14))="united states"),"United States",IF(OR(LOWER(TRIM(L14))="spain",LOWER(TRIM(L14))="españa",LOWER(TRIM(L14))="espana"),"Spain",IF(OR(LOWER(TRIM(L14))="mexico",LOWER(TRIM(L14))="méxico"),"Mexico",PROPER(LOWER(TRIM(L14))))))) -> Argentina | N14: LinkedIn | O14: Data Automation | P14: Won | Q14: =IF(P14="","",PROPER(LOWER(TRIM(P14)))) -> Won | R14: 350 | S14: 46051 | T14: 46051 | U14: Send proposal
A15: ALM-0200 | B15: Camila Torres | C15: camila.torres47@company.com | D15: =LOWER(TRIM(C15)) -> camila.torres47@company.com | G15: =IF(D15="","Missing Email",IF(COUNTIF($D$2:$D$201,D15)>1,"Duplicate","Unique")) -> Duplicate | H15: REMOVE — Exact duplicate of ALM-0014 | I15: =IFERROR(__xludf.DUMMYFUNCTION("IF(C15="""",""Missing"",IF(REGEXMATCH(C15,""^[^@\s]+@[^@\s]+\.[^@\s]+$""),""Valid"",""Invalid""))"),"Valid") -> Valid | L15: spain | M15: =IF(L15="","",IF(OR(LOWER(TRIM(L15))="u.s.a.",LOWER(TRIM(L15))="united states"),"United States",IF(OR(LOWER(TRIM(L15))="spain",LOWER(TRIM(L15))="españa",LOWER(TRIM(L15))="espana"),"Spain",IF(OR(LOWER(TRIM(L15))="mexico",LOWER(TRIM(L15))="méxico"),"Mexico",PROPER(LOWER(TRIM(L15))))))) -> Spain | N15: Website | O15: Workflow Automation | P15: Proposal Sent | Q15: =IF(P15="","",PROPER(LOWER(TRIM(P15)))) -> Proposal Sent | R15: 1500 | S15: 46030 | T15: 46043 | U15: Follow up next week
A16: ALM-0015 | B16: Sergio Ortiz | C16: sergio.ortiz49@company.com | D16: =LOWER(TRIM(C16)) -> sergio.ortiz49@company.com | G16: =IF(D16="","Missing Email",IF(COUNTIF($D$2:$D$201,D16)>1,"Duplicate","Unique")) -> Unique | I16: =IFERROR(__xludf.DUMMYFUNCTION("IF(C16="""",""Missing"",IF(REGEXMATCH(C16,""^[^@\s]+@[^@\s]+\.[^@\s]+$""),""Valid"",""Invalid""))"),"Valid") -> Valid | J16: +1-8301135501 | K16: Vision Partners | L16: United States | M16: =IF(L16="","",IF(OR(LOWER(TRIM(L16))="u.s.a.",LOWER(TRIM(L16))="united states"),"United States",IF(OR(LOWER(TRIM(L16))="spain",LOWER(TRIM(L16))="españa",LOWER(TRIM(L16))="espana"),"Spain",IF(OR(LOWER(TRIM(L16))="mexico",LOWER(TRIM(L16))="méxico"),"Mexico",PROPER(LOWER(TRIM(L16))))))) -> United States | N16: Website | O16: Document Processing | P16: New | Q16: =IF(P16="","",PROPER(LOWER(TRIM(P16)))) -> New | R16: 2500 | S16: 46070 | T16: 46081 | U16: Requested demo
A17: ALM-0016 | B17: Javier Díaz | C17: javier.diaz69@gmail.com | D17: =LOWER(TRIM(C17)) -> javier.diaz69@gmail.com | G17: =IF(D17="","Missing Email",IF(COUNTIF($D$2:$D$201,D17)>1,"Duplicate","Unique")) -> Unique | I17: =IFERROR(__xludf.DUMMYFUNCTION("IF(C17="""",""Missing"",IF(REGEXMATCH(C17,""^[^@\s]+@[^@\s]+\.[^@\s]+$""),""Valid"",""Invalid""))"),"Valid") -> Valid | J17: 425439667 | K17: Nova Partners | L17: PERU | M17: =IF(L17="","",IF(OR(LOWER(TRIM(L17))="u.s.a.",LOWER(TRIM(L17))="united states"),"United States",IF(OR(LOWER(TRIM(L17))="spain",LOWER(TRIM(L17))="españa",LOWER(TRIM(L17))="espana"),"Spain",IF(OR(LOWER(TRIM(L17))="mexico",LOWER(TRIM(L17))="méxico"),"Mexico",PROPER(LOWER(TRIM(L17))))))) -> Peru | N17: Organic Search | O17: Document Processing | P17: Lost | Q17: =IF(P17="","",PROPER(LOWER(TRIM(P17)))) -> Lost | R17: 350 | S17: 46137 | T17: 46175 | U17: Follow up next week
A18: ALM-0017 | B18: Javier Martínez | C18: javier.martinez59@mail.com | D18: =LOWER(TRIM(C18)) -> javier.martinez59@mail.com | G18: =IF(D18="","Missing Email",IF(COUNTIF($D$2:$D$201,D18)>1,"Duplicate","Unique")) -> Unique | I18: =IFERROR(__xludf.DUMMYFUNCTION("IF(C18="""",""Missing"",IF(REGEXMATCH(C18,""^[^@\s]+@[^@\s]+\.[^@\s]+$""),""Valid"",""Invalid""))"),"Valid") -> Valid | J18: 2133177044 | K18: Apex Solutions | L18: Argentina | M18: =IF(L18="","",IF(OR(LOWER(TRIM(L18))="u.s.a.",LOWER(TRIM(L18))="united states"),"United States",IF(OR(LOWER(TRIM(L18))="spain",LOWER(TRIM(L18))="españa",LOWER(TRIM(L18))="espana"),"Spain",IF(OR(LOWER(TRIM(L18))="mexico",LOWER(TRIM(L18))="méxico"),"Mexico",PROPER(LOWER(TRIM(L18))))))) -> Argentina | N18: Facebook | O18: Document Processing | P18: Qualified | Q18: =IF(P18="","",PROPER(LOWER(TRIM(P18)))) -> Qualified | R18: 2000 | S18: 46045 | T18: 46079 | U18: Requested demo
A19: ALM-0018 | B19: Isabel Gómez | C19: isabel.gomez32@mail.com | D19: =LOWER(TRIM(C19)) -> isabel.gomez32@mail.com | G19: =IF(D19="","Missing Email",IF(COUNTIF($D$2:$D$201,D19)>1,"Duplicate","Unique")) -> Unique | I19: =IFERROR(__xludf.DUMMYFUNCTION("IF(C19="""",""Missing"",IF(REGEXMATCH(C19,""^[^@\s]+@[^@\s]+\.[^@\s]+$""),""Valid"",""Invalid""))"),"Valid") -> Valid | J19: 825136069 | K19: Apex Consulting | L19: Perú | M19: =IF(L19="","",IF(OR(LOWER(TRIM(L19))="u.s.a.",LOWER(TRIM(L19))="united states"),"United States",IF(OR(LOWER(TRIM(L19))="spain",LOWER(TRIM(L19))="españa",LOWER(TRIM(L19))="espana"),"Spain",IF(OR(LOWER(TRIM(L19))="mexico",LOWER(TRIM(L19))="méxico"),"Mexico",PROPER(LOWER(TRIM(L19))))))) -> Perú | N19: Website | O19: Document Processing | P19: Lost | Q19: =IF(P19="","",PROPER(LOWER(TRIM(P19)))) -> Lost | R19: 4500 | S19: 46245 | T19: 46255 | U19: Send proposal
A20: ALM-0019 | B20: Luis Rodríguez | C20: luis.rodriguez98@gmail.com | D20: =LOWER(TRIM(C20)) -> luis.rodriguez98@gmail.com | G20: =IF(D20="","Missing Email",IF(COUNTIF($D$2:$D$201,D20)>1,"Duplicate","Unique")) -> Unique | I20: =IFERROR(__xludf.DUMMYFUNCTION("IF(C20="""",""Missing"",IF(REGEXMATCH(C20,""^[^@\s]+@[^@\s]+\.[^@\s]+$""),""Valid"",""Invalid""))"),"Valid") -> Valid | J20: +51 380 353 771 | K20: Atlas Consulting | L20: PERU | M20: =IF(L20="","",IF(OR(LOWER(TRIM(L20))="u.s.a.",LOWER(TRIM(L20))="united states"),"United States",IF(OR(LOWER(TRIM(L20))="spain",LOWER(TRIM(L20))="españa",LOWER(TRIM(L20))="espana"),"Spain",IF(OR(LOWER(TRIM(L20))="mexico",LOWER(TRIM(L20))="méxico"),"Mexico",PROPER(LOWER(TRIM(L20))))))) -> Peru | N20: Referral | O20: Data Automation | P20: New | Q20: =IF(P20="","",PROPER(LOWER(TRIM(P20)))) -> New | R20: 3000 | S20: 46037 | T20: 46053 | U20: Needs pricing
A21: ALM-0020 | B21: Natalia Díaz | C21: natalia.diaz38@mail.com | D21: =LOWER(TRIM(C21)) -> natalia.diaz38@mail.com | G21: =IF(D21="","Missing Email",IF(COUNTIF($D$2:$D$201,D21)>1,"Duplicate","Unique")) -> Unique | I21: =IFERROR(__xludf.DUMMYFUNCTION("IF(C21="""",""Missing"",IF(REGEXMATCH(C21,""^[^@\s]+@[^@\s]+\.[^@\s]+$""),""Valid"",""Invalid""))"),"Valid") -> Valid | J21: +503 574 493 38 | K21: Prime Group | L21: EL SALVADOR | M21: =IF(L21="","",IF(OR(LOWER(TRIM(L21))="u.s.a.",LOWER(TRIM(L21))="united states"),"United States",IF(OR(LOWER(TRIM(L21))="spain",LOWER(TRIM(L21))="españa",LOWER(TRIM(L21))="espana"),"Spain",IF(OR(LOWER(TRIM(L21))="mexico",LOWER(TRIM(L21))="méxico"),"Mexico",PROPER(LOWER(TRIM(L21))))))) -> El Salvador | N21: Referral | O21: Document Processing | P21: Contacted | Q21: =IF(P21="","",PROPER(LOWER(TRIM(P21)))) -> Contacted | R21: 1200 | S21: 46231 | T21: 46231
A22: ALM-0021 | B22: Daniel Flores | C22: daniel.flores94@outlook.com | D22: =LOWER(TRIM(C22)) -> daniel.flores94@outlook.com | G22: =IF(D22="","Missing Email",IF(COUNTIF($D$2:$D$201,D22)>1,"Duplicate","Unique")) -> Unique | I22: =IFERROR(__xludf.DUMMYFUNCTION("IF(C22="""",""Missing"",IF(REGEXMATCH(C22,""^[^@\s]+@[^@\s]+\.[^@\s]+$""),""Valid"",""Invalid""))"),"Valid") -> Valid | J22: 61320024 | K22: Urban Commerce | L22: El Salvador | M22: =IF(L22="","",IF(OR(LOWER(TRIM(L22))="u.s.a.",LOWER(TRIM(L22))="united states"),"United States",IF(OR(LOWER(TRIM(L22))="spain",LOWER(TRIM(L22))="españa",LOWER(TRIM(L22))="espana"),"Spain",IF(OR(LOWER(TRIM(L22))="mexico",LOWER(TRIM(L22))="méxico"),"Mexico",PROPER(LOWER(TRIM(L22))))))) -> El Salvador | N22: Instagram | O22: Data Automation | P22: New | Q22: =IF(P22="","",PROPER(LOWER(TRIM(P22)))) -> New | R22: 500 | S22: 46232 | T22: 46263 | U22: Needs pricing
A23: ALM-0060 | B23: Carlos Pérez | C23: carlos.perez33@gmail.com | D23: =LOWER(TRIM(C23)) -> carlos.perez33@gmail.com | G23: =IF(D23="","Missing Email",IF(COUNTIF($D$2:$D$201,D23)>1,"Duplicate","Unique")) -> Duplicate | I23: =IFERROR(__xludf.DUMMYFUNCTION("IF(C23="""",""Missing"",IF(REGEXMATCH(C23,""^[^@\s]+@[^@\s]+\.[^@\s]+$""),""Valid"",""Invalid""))"),"Valid") -> Valid | J23: +1-3771357664 | K23: Bright Works | L23: united states | M23: =IF(L23="","",IF(OR(LOWER(TRIM(L23))="u.s.a.",LOWER(TRIM(L23))="united states"),"United States",IF(OR(LOWER(TRIM(L23))="spain",LOWER(TRIM(L23))="españa",LOWER(TRIM(L23))="espana"),"Spain",IF(OR(LOWER(TRIM(L23))="mexico",LOWER(TRIM(L23))="méxico"),"Mexico",PROPER(LOWER(TRIM(L23))))))) -> United States | N23: Referral | O23: Document Processing | P23: Qualified | Q23: =IF(P23="","",PROPER(LOWER(TRIM(P23)))) -> Qualified | R23: 1500 | S23: 46253 | T23: 46275 | U23: Interested in automation
A24: ALM-0023 | B24: Raúl Hernández | C24: raul.hernandez69@company.com | D24: =LOWER(TRIM(C24)) -> raul.hernandez69@company.com | G24: =IF(D24="","Missing Email",IF(COUNTIF($D$2:$D$201,D24)>1,"Duplicate","Unique")) -> Unique | I24: =IFERROR(__xludf.DUMMYFUNCTION("IF(C24="""",""Missing"",IF(REGEXMATCH(C24,""^[^@\s]+@[^@\s]+\.[^@\s]+$""),""Valid"",""Invalid""))"),"Valid") -> Valid | J24: 1239353409 | K24: Vertex Solutions | L24: argentina | M24: =IF(L24="","",IF(OR(LOWER(TRIM(L24))="u.s.a.",LOWER(TRIM(L24))="united states"),"United States",IF(OR(LOWER(TRIM(L24))="spain",LOWER(TRIM(L24))="españa",LOWER(TRIM(L24))="espana"),"Spain",IF(OR(LOWER(TRIM(L24))="mexico",LOWER(TRIM(L24))="méxico"),"Mexico",PROPER(LOWER(TRIM(L24))))))) -> Argentina | N24: Organic Search | O24: AI Voice Agent | P24: Contacted | Q24: =IF(P24="","",PROPER(LOWER(TRIM(P24)))) -> Contacted | R24: 750 | S24: 46149 | T24: 46157 | U24: Interested in automation
A25: ALM-0024 | B25: Sergio Hernández | C25: sergio.hernandez12@outlook.com | D25: =LOWER(TRIM(C25)) -> sergio.hernandez12@outlook.com | G25: =IF(D25="","Missing Email",IF(COUNTIF($D$2:$D$201,D25)>1,"Duplicate","Unique")) -> Unique | I25: =IFERROR(__xludf.DUMMYFUNCTION("IF(C25="""",""Missing"",IF(REGEXMATCH(C25,""^[^@\s]+@[^@\s]+\.[^@\s]+$""),""Valid"",""Invalid""))"),"Valid") -> Valid | J25: +57 299 254 3784 | K25: Sol Commerce | L25: colombia | M25: =IF(L25="","",IF(OR(LOWER(TRIM(L25))="u.s.a.",LOWER(TRIM(L25))="united states"),"United States",IF(OR(LOWER(TRIM(L25))="spain",LOWER(TRIM(L25))="españa",LOWER(TRIM(L25))="espana"),"Spain",IF(OR(LOWER(TRIM(L25))="mexico",LOWER(TRIM(L25))="méxico"),"Mexico",PROPER(LOWER(TRIM(L25))))))) -> Colombia | N25: Website | O25: Data Automation | P25: Won | Q25: =IF(P25="","",PROPER(LOWER(TRIM(P25)))) -> Won | R25: 2500 | S25: 46033 | T25: 46069 | U25: Interested in automation
A26: ALM-0025 | B26: Paula Díaz | C26: paula.diaz76@mail.com | D26: =LOWER(TRIM(C26)) -> paula.diaz76@mail.com | G26: =IF(D26="","Missing Email",IF(COUNTIF($D$2:$D$201,D26)>1,"Duplicate","Unique")) -> Unique | I26: =IFERROR(__xludf.DUMMYFUNCTION("IF(C26="""",""Missing"",IF(REGEXMATCH(C26,""^[^@\s]+@[^@\s]+\.[^@\s]+$""),""Valid"",""Invalid""))"),"Valid") -> Valid | K26: MOMENTUM SERVICES | L26: Peru | M26: =IF(L26="","",IF(OR(LOWER(TRIM(L26))="u.s.a.",LOWER(TRIM(L26))="united states"),"United States",IF(OR(LOWER(TRIM(L26))="spain",LOWER(TRIM(L26))="españa",LOWER(TRIM(L26))="espana"),"Spain",IF(OR(LOWER(TRIM(L26))="mexico",LOWER(TRIM(L26))="méxico"),"Mexico",PROPER(LOWER(TRIM(L26))))))) -> Peru | N26: Referral | O26: Workflow Automation | P26: Qualified | Q26: =IF(P26="","",PROPER(LOWER(TRIM(P26)))) -> Qualified | R26: 4500 | S26: 46032 | T26: 46068
A27: ALM-0026 | B27: Diego García | C27: diego.garcia78@gmail.com | D27: =LOWER(TRIM(C27)) -> diego.garcia78@gmail.com | G27: =IF(D27="","Missing Email",IF(COUNTIF($D$2:$D$201,D27)>1,"Duplicate","Unique")) -> Unique | I27: =IFERROR(__xludf.DUMMYFUNCTION("IF(C27="""",""Missing"",IF(REGEXMATCH(C27,""^[^@\s]+@[^@\s]+\.[^@\s]+$""),""Valid"",""Invalid""))"),"Valid") -> Valid | J27: 2309827434 | K27: Vision Services | L27: ARGENTINA | M27: =IF(L27="","",IF(OR(LOWER(TRIM(L27))="u.s.a.",LOWER(TRIM(L27))="united states"),"United States",IF(OR(LOWER(TRIM(L27))="spain",LOWER(TRIM(L27))="españa",LOWER(TRIM(L27))="espana"),"Spain",IF(OR(LOWER(TRIM(L27))="mexico",LOWER(TRIM(L27))="méxico"),"Mexico",PROPER(LOWER(TRIM(L27))))))) -> Argentina | N27: Organic Search | O27: Workflow Automation | P27: New | Q27: =IF(P27="","",PROPER(LOWER(TRIM(P27)))) -> New | R27: 1500 | S27: 46253 | T27: 46286 | U27: Requested demo
A28: ALM-0027 | B28: Daniel Pérez | C28: daniel.perez13 @ gmail.com | D28: =LOWER(TRIM(C28)) -> daniel.perez13 @ gmail.com | E28: AUTO-FIX — Remove internal spaces | F28: daniel.perez13@gmail.com | G28: =IF(D28="","Missing Email",IF(COUNTIF($D$2:$D$201,D28)>1,"Duplicate","Unique")) -> Unique | I28: =IFERROR(__xludf.DUMMYFUNCTION("IF(C28="""",""Missing"",IF(REGEXMATCH(C28,""^[^@\s]+@[^@\s]+\.[^@\s]+$""),""Valid"",""Invalid""))"),"Invalid") -> Invalid | K28: Bright Solutions | L28: argentina | M28: =IF(L28="","",IF(OR(LOWER(TRIM(L28))="u.s.a.",LOWER(TRIM(L28))="united states"),"United States",IF(OR(LOWER(TRIM(L28))="spain",LOWER(TRIM(L28))="españa",LOWER(TRIM(L28))="espana"),"Spain",IF(OR(LOWER(TRIM(L28))="mexico",LOWER(TRIM(L28))="méxico"),"Mexico",PROPER(LOWER(TRIM(L28))))))) -> Argentina | N28: Instagram | O28: Data Automation | P28: Won | Q28: =IF(P28="","",PROPER(LOWER(TRIM(P28)))) -> Won | R28: 350 | S28: 46121 | T28: 46153 | U28: Send proposal
A29: ALM-0028 | B29: Fernando Morales | C29: fernando.morales39@company.com | D29: =LOWER(TRIM(C29)) -> fernando.morales39@company.com | G29: =IF(D29="","Missing Email",IF(COUNTIF($D$2:$D$201,D29)>1,"Duplicate","Unique")) -> Unique | I29: =IFERROR(__xludf.DUMMYFUNCTION("IF(C29="""",""Missing"",IF(REGEXMATCH(C29,""^[^@\s]+@[^@\s]+\.[^@\s]+$""),""Valid"",""Invalid""))"),"Valid") -> Valid | J29: +54 5898158879 | K29: Prime Labs | L29: ARGENTINA | M29: =IF(L29="","",IF(OR(LOWER(TRIM(L29))="u.s.a.",LOWER(TRIM(L29))="united states"),"United States",IF(OR(LOWER(TRIM(L29))="spain",LOWER(TRIM(L29))="españa",LOWER(TRIM(L29))="espana"),"Spain",IF(OR(LOWER(TRIM(L29))="mexico",LOWER(TRIM(L29))="méxico"),"Mexico",PROPER(LOWER(TRIM(L29))))))) -> Argentina | N29: Website | O29: AI Voice Agent | P29: Won | Q29: =IF(P29="","",PROPER(LOWER(TRIM(P29)))) -> Won | R29: 4500 | S29: 46206 | T29: 46206 | U29: Interested in automation
A30: ALM-0029 | B30: Alejandro Torres | C30: alejandro.torres56@company.com | D30: =LOWER(TRIM(C30)) -> alejandro.torres56@company.com | G30: =IF(D30="","Missing Email",IF(COUNTIF($D$2:$D$201,D30)>1,"Duplicate","Unique")) -> Unique | I30: =IFERROR(__xludf.DUMMYFUNCTION("IF(C30="""",""Missing"",IF(REGEXMATCH(C30,""^[^@\s]+@[^@\s]+\.[^@\s]+$""),""Valid"",""Invalid""))"),"Valid") -> Valid | J30: +52 0203959259 | K30: Cloud Commerce | L30: Mexico | M30: =IF(L30="","",IF(OR(LOWER(TRIM(L30))="u.s.a.",LOWER(TRIM(L30))="united states"),"United States",IF(OR(LOWER(TRIM(L30))="spain",LOWER(TRIM(L30))="españa",LOWER(TRIM(L30))="espana"),"Spain",IF(OR(LOWER(TRIM(L30))="mexico",LOWER(TRIM(L30))="méxico"),"Mexico",PROPER(LOWER(TRIM(L30))))))) -> Mexico | N30: Organic Search | O30: AI Voice Agent | P30: Qualified | Q30: =IF(P30="","",PROPER(LOWER(TRIM(P30)))) -> Qualified | R30: 3000 | S30: 46103 | T30: 46112
A31: ALM-0030 | B31: Alejandro Ramírez | C31: alejandro.ramirez44@company.com | D31: =LOWER(TRIM(C31)) -> alejandro.ramirez44@company.com | G31: =IF(D31="","Missing Email",IF(COUNTIF($D$2:$D$201,D31)>1,"Duplicate","Unique")) -> Unique | I31: =IFERROR(__xludf.DUMMYFUNCTION("IF(C31="""",""Missing"",IF(REGEXMATCH(C31,""^[^@\s]+@[^@\s]+\.[^@\s]+$""),""Valid"",""Invalid""))"),"Valid") -> Valid | L31: chile | M31: =IF(L31="","",IF(OR(LOWER(TRIM(L31))="u.s.a.",LOWER(TRIM(L31))="united states"),"United States",IF(OR(LOWER(TRIM(L31))="spain",LOWER(TRIM(L31))="españa",LOWER(TRIM(L31))="espana"),"Spain",IF(OR(LOWER(TRIM(L31))="mexico",LOWER(TRIM(L31))="méxico"),"Mexico",PROPER(LOWER(TRIM(L31))))))) -> Chile | N31: Facebook | O31: Data Automation | P31: New | Q31: =IF(P31="","",PROPER(LOWER(TRIM(P31)))) -> New | R31: 2500 | S31: 46134 | T31: 46169 | U31: Interested in automation
A32: ALM-0031 | B32: Raúl Rodríguez | C32: raul.rodriguez57@gmail.com | D32: =LOWER(TRIM(C32)) -> raul.rodriguez57@gmail.com | G32: =IF(D32="","Missing Email",IF(COUNTIF($D$2:$D$201,D32)>1,"Duplicate","Unique")) -> Unique | I32: =IFERROR(__xludf.DUMMYFUNCTION("IF(C32="""",""Missing"",IF(REGEXMATCH(C32,""^[^@\s]+@[^@\s]+\.[^@\s]+$""),""Valid"",""Invalid""))"),"Valid") -> Valid | J32: +52-8554682838 | K32: Blue Studio | L32: México | M32: =IF(L32="","",IF(OR(LOWER(TRIM(L32))="u.s.a.",LOWER(TRIM(L32))="united states"),"United States",IF(OR(LOWER(TRIM(L32))="spain",LOWER(TRIM(L32))="españa",LOWER(TRIM(L32))="espana"),"Spain",IF(OR(LOWER(TRIM(L32))="mexico",LOWER(TRIM(L32))="méxico"),"Mexico",PROPER(LOWER(TRIM(L32))))))) -> Mexico | N32: Facebook | O32: Document Processing | P32: Proposal Sent | Q32: =IF(P32="","",PROPER(LOWER(TRIM(P32)))) -> Proposal Sent | R32: 750 | S32: 46183 | T32: 46216
A33: ALM-0032 | B33: Diego Navarro | C33: diego.navarro64@mail.com | D33: =LOWER(TRIM(C33)) -> diego.navarro64@mail.com | G33: =IF(D33="","Missing Email",IF(COUNTIF($D$2:$D$201,D33)>1,"Duplicate","Unique")) -> Unique | I33: =IFERROR(__xludf.DUMMYFUNCTION("IF(C33="""",""Missing"",IF(REGEXMATCH(C33,""^[^@\s]+@[^@\s]+\.[^@\s]+$""),""Valid"",""Invalid""))"),"Valid") -> Valid | K33: Blue Services | L33: Salvador | M33: =IF(L33="","",IF(OR(LOWER(TRIM(L33))="u.s.a.",LOWER(TRIM(L33))="united states"),"United States",IF(OR(LOWER(TRIM(L33))="spain",LOWER(TRIM(L33))="españa",LOWER(TRIM(L33))="espana"),"Spain",IF(OR(LOWER(TRIM(L33))="mexico",LOWER(TRIM(L33))="méxico"),"Mexico",PROPER(LOWER(TRIM(L33))))))) -> Salvador | N33: Organic Search | O33: Website Chat Agent | P33: New | Q33: =IF(P33="","",PROPER(LOWER(TRIM(P33)))) -> New | S33: 46095 | T33: 46099 | U33: Interested in automation
A34: ALM-0033 | B34: Andrés Sánchez | C34: andres.sanchez74@outlook.com | D34: =LOWER(TRIM(C34)) -> andres.sanchez74@outlook.com | G34: =IF(D34="","Missing Email",IF(COUNTIF($D$2:$D$201,D34)>1,"Duplicate","Unique")) -> Unique | I34: =IFERROR(__xludf.DUMMYFUNCTION("IF(C34="""",""Missing"",IF(REGEXMATCH(C34,""^[^@\s]+@[^@\s]+\.[^@\s]+$""),""Valid"",""Invalid""))"),"Valid") -> Valid | J34: +1-4772755215 | K34: Urban Works | L34: United States | M34: =IF(L34="","",IF(OR(LOWER(TRIM(L34))="u.s.a.",LOWER(TRIM(L34))="united states"),"United States",IF(OR(LOWER(TRIM(L34))="spain",LOWER(TRIM(L34))="españa",LOWER(TRIM(L34))="espana"),"Spain",IF(OR(LOWER(TRIM(L34))="mexico",LOWER(TRIM(L34))="méxico"),"Mexico",PROPER(LOWER(TRIM(L34))))))) -> United States | N34: Organic Search | O34: Website Chat Agent | P34: Won | Q34: =IF(P34="","",PROPER(LOWER(TRIM(P34)))) -> Won | R34: 750 | S34: 46190 | T34: 46192 | U34: Requested demo
A35: ALM-0034 | B35: Manuel Morales | C35: manuel.morales27@gmail.com | D35: =LOWER(TRIM(C35)) -> manuel.morales27@gmail.com | G35: =IF(D35="","Missing Email",IF(COUNTIF($D$2:$D$201,D35)>1,"Duplicate","Unique")) -> Unique | I35: =IFERROR(__xludf.DUMMYFUNCTION("IF(C35="""",""Missing"",IF(REGEXMATCH(C35,""^[^@\s]+@[^@\s]+\.[^@\s]+$""),""Valid"",""Invalid""))"),"Valid") -> Valid | J35: 881839487 | K35: Sol Labs | L35: peru | M35: =IF(L35="","",IF(OR(LOWER(TRIM(L35))="u.s.a.",LOWER(TRIM(L35))="united states"),"United States",IF(OR(LOWER(TRIM(L35))="spain",LOWER(TRIM(L35))="españa",LOWER(TRIM(L35))="espana"),"Spain",IF(OR(LOWER(TRIM(L35))="mexico",LOWER(TRIM(L35))="méxico"),"Mexico",PROPER(LOWER(TRIM(L35))))))) -> Peru | N35: Website | O35: AI Voice Agent | P35: Won | Q35: =IF(P35="","",PROPER(LOWER(TRIM(P35)))) -> Won | R35: 3000 | S35: 46030 | T35: 46052 | U35: Follow up next week
A36: ALM-0035 | B36: Alejandro Sánchez | C36: alejandro.sanchez42@mail.com | D36: =LOWER(TRIM(C36)) -> alejandro.sanchez42@mail.com | G36: =IF(D36="","Missing Email",IF(COUNTIF($D$2:$D$201,D36)>1,"Duplicate","Unique")) -> Unique | I36: =IFERROR(__xludf.DUMMYFUNCTION("IF(C36="""",""Missing"",IF(REGEXMATCH(C36,""^[^@\s]+@[^@\s]+\.[^@\s]+$""),""Valid"",""Invalid""))"),"Valid") -> Valid | J36: +57 406 830 4098 | K36: Apex Services | L36: colombia | M36: =IF(L36="","",IF(OR(LOWER(TRIM(L36))="u.s.a.",LOWER(TRIM(L36))="united states"),"United States",IF(OR(LOWER(TRIM(L36))="spain",LOWER(TRIM(L36))="españa",LOWER(TRIM(L36))="espana"),"Spain",IF(OR(LOWER(TRIM(L36))="mexico",LOWER(TRIM(L36))="méxico"),"Mexico",PROPER(LOWER(TRIM(L36))))))) -> Colombia | N36: Instagram | O36: Data Automation | P36: Lost | Q36: =IF(P36="","",PROPER(LOWER(TRIM(P36)))) -> Lost | R36: 500 | S36: 46092 | T36: 46135
A37: ALM-0036 | B37: Patricia Díaz | C37: patricia.diaz43@company.com | D37: =LOWER(TRIM(C37)) -> patricia.diaz43@company.com | G37: =IF(D37="","Missing Email",IF(COUNTIF($D$2:$D$201,D37)>1,"Duplicate","Unique")) -> Unique | I37: =IFERROR(__xludf.DUMMYFUNCTION("IF(C37="""",""Missing"",IF(REGEXMATCH(C37,""^[^@\s]+@[^@\s]+\.[^@\s]+$""),""Valid"",""Invalid""))"),"Valid") -> Valid | J37: +503 323 170 50 | K37: Vertex Labs | L37: El Salvador | M37: =IF(L37="","",IF(OR(LOWER(TRIM(L37))="u.s.a.",LOWER(TRIM(L37))="united states"),"United States",IF(OR(LOWER(TRIM(L37))="spain",LOWER(TRIM(L37))="españa",LOWER(TRIM(L37))="espana"),"Spain",IF(OR(LOWER(TRIM(L37))="mexico",LOWER(TRIM(L37))="méxico"),"Mexico",PROPER(LOWER(TRIM(L37))))))) -> El Salvador | N37: Organic Search | O37: Website Chat Agent | P37: Proposal Sent | Q37: =IF(P37="","",PROPER(LOWER(TRIM(P37)))) -> Proposal Sent | R37: 4500 | S37: 46035 | T37: 46080 | U37: Needs pricing
A38: ALM-0037 | B38: David Torres | C38: david.torres10@company.com | D38: =LOWER(TRIM(C38)) -> david.torres10@company.com | G38: =IF(D38="","Missing Email",IF(COUNTIF($D$2:$D$201,D38)>1,"Duplicate","Unique")) -> Unique | I38: =IFERROR(__xludf.DUMMYFUNCTION("IF(C38="""",""Missing"",IF(REGEXMATCH(C38,""^[^@\s]+@[^@\s]+\.[^@\s]+$""),""Valid"",""Invalid""))"),"Valid") -> Valid | J38: +56 625 147 716 | K38: Bright Commerce | L38: CHILE | M38: =IF(L38="","",IF(OR(LOWER(TRIM(L38))="u.s.a.",LOWER(TRIM(L38))="united states"),"United States",IF(OR(LOWER(TRIM(L38))="spain",LOWER(TRIM(L38))="españa",LOWER(TRIM(L38))="espana"),"Spain",IF(OR(LOWER(TRIM(L38))="mexico",LOWER(TRIM(L38))="méxico"),"Mexico",PROPER(LOWER(TRIM(L38))))))) -> Chile | N38: Referral | O38: Website Chat Agent | P38: Lost | Q38: =IF(P38="","",PROPER(LOWER(TRIM(P38)))) -> Lost | R38: 3000 | S38: 46134 | T38: 46154 | U38: Requested demo
A39: ALM-0038 | B39: Fernando Romero | C39: fernando.romero63@gmail.com | D39: =LOWER(TRIM(C39)) -> fernando.romero63@gmail.com | G39: =IF(D39="","Missing Email",IF(COUNTIF($D$2:$D$201,D39)>1,"Duplicate","Unique")) -> Unique | I39: =IFERROR(__xludf.DUMMYFUNCTION("IF(C39="""",""Missing"",IF(REGEXMATCH(C39,""^[^@\s]+@[^@\s]+\.[^@\s]+$""),""Valid"",""Invalid""))"),"Valid") -> Valid | J39: 5161885601 | K39: Apex Labs | L39: COLOMBIA | M39: =IF(L39="","",IF(OR(LOWER(TRIM(L39))="u.s.a.",LOWER(TRIM(L39))="united states"),"United States",IF(OR(LOWER(TRIM(L39))="spain",LOWER(TRIM(L39))="españa",LOWER(TRIM(L39))="espana"),"Spain",IF(OR(LOWER(TRIM(L39))="mexico",LOWER(TRIM(L39))="méxico"),"Mexico",PROPER(LOWER(TRIM(L39))))))) -> Colombia | N39: LinkedIn | O39: Data Automation | P39: Proposal Sent | Q39: =IF(P39="","",PROPER(LOWER(TRIM(P39)))) -> Proposal Sent | R39: 350 | S39: 46153 | T39: 46161 | U39: Send proposal
A40: ALM-0039 | B40: Fernando Rivera | C40: fernando.rivera80@company.com | D40: =LOWER(TRIM(C40)) -> fernando.rivera80@company.com | G40: =IF(D40="","Missing Email",IF(COUNTIF($D$2:$D$201,D40)>1,"Duplicate","Unique")) -> Unique | I40: =IFERROR(__xludf.DUMMYFUNCTION("IF(C40="""",""Missing"",IF(REGEXMATCH(C40,""^[^@\s]+@[^@\s]+\.[^@\s]+$""),""Valid"",""Invalid""))"),"Valid") -> Valid | J40: +57 1778362014 | L40: colombia | M40: =IF(L40="","",IF(OR(LOWER(TRIM(L40))="u.s.a.",LOWER(TRIM(L40))="united states"),"United States",IF(OR(LOWER(TRIM(L40))="spain",LOWER(TRIM(L40))="españa",LOWER(TRIM(L40))="espana"),"Spain",IF(OR(LOWER(TRIM(L40))="mexico",LOWER(TRIM(L40))="méxico"),"Mexico",PROPER(LOWER(TRIM(L40))))))) -> Colombia | N40: Instagram | O40: Workflow Automation | P40: Won | Q40: =IF(P40="","",PROPER(LOWER(TRIM(P40)))) -> Won | R40: 350 | S40: 46090 | T40: 46090 | U40: Interested in automation
...

Sheet FINAL_DATA
A1: Record_ID | B1: Full_Name | C1: Email | D1: Phone | E1: Company | F1: Country | G1: Lead_Source | H1: Service_Interest | I1: Lead_Status | J1: Estimated_Value_USD | K1: Created_Date | L1: Last_Contact_Date | M1: Notes
A2: ALM-0001 | B2: Alejandro Navarro | C2: alejandro.navarro94@company.com | D2: 201539268 | E2: Apex Studio | F2: Chile | G2: Organic Search | H2: Document Processing | I2: Contacted | K2: 46111 | L2: 46153 | M2: Follow up next week
A3: ALM-0072 | B3: Camila González | C3: camila.gonzalez86@mail.com | D3: +56-124965231 | E3: Digital Labs | F3: Chile | G3: Instagram | H3: Workflow Automation | I3: Contacted | J3: 3000 | K3: 46088 | L3: 46113 | M3: Requested demo
A4: ALM-0003 | B4: Carlos Navarro | C4: carlos.navarro11@mail.com | D4: +503 23813586 | E4: Momentum Services | F4: El Salvador | G4: Referral | H4: AI Voice Agent | I4: New | J4: 500 | K4: 46101
A5: ALM-0004 | B5: María González | C5: maria.gonzalez3@outlook.com | D5: +54 8433709892 | E5: Sol Partners | F5: Argentina | G5: Website | H5: AI Voice Agent | I5: Lost | J5: 1500 | K5: 46215 | L5: 46244 | M5: Follow up next week
A6: ALM-0005 | B6: Carolina Navarro | C6: carolina.navarro41@gmail.com | D6: +51 696 199 746 | E6: Bright Partners | F6: Peru | G6: Referral | H6: AI Voice Agent | I6: Won | J6: 350 | K6: 46174 | L6: 46191 | M6: Interested in automation
A7: ALM-0007 | B7: María Rivera | C7: maria.rivera61@outlook.com | D7: +1 2474157676 | E7: CLOUD SOLUTIONS | F7: United States | G7: Instagram | H7: Data Automation | I7: Proposal Sent | J7: 500 | K7: 46052 | L7: 46087 | M7: Requested demo
A8: ALM-0014 | B8: Camila Torres | C8: camila.torres47@company.com | F8: Spain | G8: Website | H8: Workflow Automation | I8: Proposal Sent | J8: 1500 | K8: 46030 | L8: 46043 | M8: Follow up next week
A9: ALM-0009 | B9: Miguel Rodríguez | C9: miguel.rodriguez72@outlook.com | D9: +503 70533950 | E9: Nova Commerce | F9: El Salvador | G9: Organic Search | H9: Document Processing | I9: Contacted | J9: 1500 | K9: 46095 | L9: 46129 | M9: Requested demo
A10: ALM-0010 | B10: Manuel López | C10: manuel.lopez9@outlook.com | D10: 2859040010 | E10: Momentum Studio | F10: Argentina | G10: Website | H10: Data Automation | I10: Proposal Sent | J10: 350 | K10: 46180 | L10: 46181 | M10: Needs pricing
A11: ALM-0011 | B11: Patricia Pérez | C11: patricia.perez5@outlook.com | D11: +34-105504239 | E11: Nexo Group | F11: Spain | G11: Website | H11: Workflow Automation | I11: Proposal Sent | J11: 1200 | K11: 46160 | M11: Interested in automation
A12: ALM-0012 | B12: Andrés Martínez | C12: andres.martinez22@mail.com | D12: +54-2437252546 | E12: Apex Services | F12: Argentina | G12: LinkedIn | H12: Document Processing | I12: Lost | J12: 900 | K12: 46179 | L12: 46199 | M12: Send proposal
A13: ALM-0013 | B13: natalia ortiz | C13: natalia.ortiz66@gmail.com | D13: +54-2332522808 | E13: Sol Solutions | F13: Argentina | G13: LinkedIn | H13: Data Automation | I13: Won | J13: 350 | K13: 46051 | L13: 46051 | M13: Send proposal
A14: ALM-0015 | B14: Sergio Ortiz | C14: sergio.ortiz49@company.com | D14: +1-8301135501 | E14: Vision Partners | F14: United States | G14: Website | H14: Document Processing | I14: New | J14: 2500 | K14: 46070 | L14: 46081 | M14: Requested demo
A15: ALM-0016 | B15: Javier Díaz | C15: javier.diaz69@gmail.com | D15: 425439667 | E15: Nova Partners | F15: Peru | G15: Organic Search | H15: Document Processing | I15: Lost | J15: 350 | K15: 46137 | L15: 46175 | M15: Follow up next week
A16: ALM-0017 | B16: Javier Martínez | C16: javier.martinez59@mail.com | D16: 2133177044 | E16: Apex Solutions | F16: Argentina | G16: Facebook | H16: Document Processing | I16: Qualified | J16: 2000 | K16: 46045 | L16: 46079 | M16: Requested demo
A17: ALM-0018 | B17: Isabel Gómez | C17: isabel.gomez32@mail.com | D17: 825136069 | E17: Apex Consulting | F17: Perú | G17: Website | H17: Document Processing | I17: Lost | J17: 4500 | K17: 46245 | L17: 46255 | M17: Send proposal
A18: ALM-0019 | B18: Luis Rodríguez | C18: luis.rodriguez98@gmail.com | D18: +51 380 353 771 | E18: Atlas Consulting | F18: Peru | G18: Referral | H18: Data Automation | I18: New | J18: 3000 | K18: 46037 | L18: 46053 | M18: Needs pricing
A19: ALM-0020 | B19: Natalia Díaz | C19: natalia.diaz38@mail.com | D19: +503 574 493 38 | E19: Prime Group | F19: El Salvador | G19: Referral | H19: Document Processing | I19: Contacted | J19: 1200 | K19: 46231 | L19: 46231
A20: ALM-0021 | B20: Daniel Flores | C20: daniel.flores94@outlook.com | D20: 61320024 | E20: Urban Commerce | F20: El Salvador | G20: Instagram | H20: Data Automation | I20: New | J20: 500 | K20: 46232 | L20: 46263 | M20: Needs pricing
A21: ALM-0060 | B21: Carlos Pérez | C21: carlos.perez33@gmail.com | D21: +1-3771357664 | E21: Bright Works | F21: United States | G21: Referral | H21: Document Processing | I21: Qualified | J21: 1500 | K21: 46253 | L21: 46275 | M21: Interested in automation
A22: ALM-0023 | B22: Raúl Hernández | C22: raul.hernandez69@company.com | D22: 1239353409 | E22: Vertex Solutions | F22: Argentina | G22: Organic Search | H22: AI Voice Agent | I22: Contacted | J22: 750 | K22: 46149 | L22: 46157 | M22: Interested in automation
A23: ALM-0024 | B23: Sergio Hernández | C23: sergio.hernandez12@outlook.com | D23: +57 299 254 3784 | E23: Sol Commerce | F23: Colombia | G23: Website | H23: Data Automation | I23: Won | J23: 2500 | K23: 46033 | L23: 46069 | M23: Interested in automation
A24: ALM-0025 | B24: Paula Díaz | C24: paula.diaz76@mail.com | E24: MOMENTUM SERVICES | F24: Peru | G24: Referral | H24: Workflow Automation | I24: Qualified | J24: 4500 | K24: 46032 | L24: 46068
A25: ALM-0026 | B25: Diego García | C25: diego.garcia78@gmail.com | D25: 2309827434 | E25: Vision Services | F25: Argentina | G25: Organic Search | H25: Workflow Automation | I25: New | J25: 1500 | K25: 46253 | L25: 46286 | M25: Requested demo
A26: ALM-0027 | B26: Daniel Pérez | C26: daniel.perez13@gmail.com | E26: Bright Solutions | F26: Argentina | G26: Instagram | H26: Data Automation | I26: Won | J26: 350 | K26: 46121 | L26: 46153 | M26: Send proposal
A27: ALM-0028 | B27: Fernando Morales | C27: fernando.morales39@company.com | D27: +54 5898158879 | E27: Prime Labs | F27: Argentina | G27: Website | H27: AI Voice Agent | I27: Won | J27: 4500 | K27: 46206 | L27: 46206 | M27: Interested in automation
A28: ALM-0029 | B28: Alejandro Torres | C28: alejandro.torres56@company.com | D28: +52 0203959259 | E28: Cloud Commerce | F28: Mexico | G28: Organic Search | H28: AI Voice Agent | I28: Qualified | J28: 3000 | K28: 46103 | L28: 46112
A29: ALM-0030 | B29: Alejandro Ramírez | C29: alejandro.ramirez44@company.com | F29: Chile | G29: Facebook | H29: Data Automation | I29: New | J29: 2500 | K29: 46134 | L29: 46169 | M29: Interested in automation
A30: ALM-0031 | B30: Raúl Rodríguez | C30: raul.rodriguez57@gmail.com | D30: +52-8554682838 | E30: Blue Studio | F30: Mexico | G30: Facebook | H30: Document Processing | I30: Proposal Sent | J30: 750 | K30: 46183 | L30: 46216
A31: ALM-0032 | B31: Diego Navarro | C31: diego.navarro64@mail.com | E31: Blue Services | F31: Salvador | G31: Organic Search | H31: Website Chat Agent | I31: New | K31: 46095 | L31: 46099 | M31: Interested in automation
A32: ALM-0033 | B32: Andrés Sánchez | C32: andres.sanchez74@outlook.com | D32: +1-4772755215 | E32: Urban Works | F32: United States | G32: Organic Search | H32: Website Chat Agent | I32: Won | J32: 750 | K32: 46190 | L32: 46192 | M32: Requested demo
A33: ALM-0034 | B33: Manuel Morales | C33: manuel.morales27@gmail.com | D33: 881839487 | E33: Sol Labs | F33: Peru | G33: Website | H33: AI Voice Agent | I33: Won | J33: 3000 | K33: 46030 | L33: 46052 | M33: Follow up next week
A34: ALM-0035 | B34: Alejandro Sánchez | C34: alejandro.sanchez42@mail.com | D34: +57 406 830 4098 | E34: Apex Services | F34: Colombia | G34: Instagram | H34: Data Automation | I34: Lost | J34: 500 | K34: 46092 | L34: 46135
A35: ALM-0036 | B35: Patricia Díaz | C35: patricia.diaz43@company.com | D35: +503 323 170 50 | E35: Vertex Labs | F35: El Salvador | G35: Organic Search | H35: Website Chat Agent | I35: Proposal Sent | J35: 4500 | K35: 46035 | L35: 46080 | M35: Needs pricing
A36: ALM-0037 | B36: David Torres | C36: david.torres10@company.com | D36: +56 625 147 716 | E36: Bright Commerce | F36: Chile | G36: Referral | H36: Website Chat Agent | I36: Lost | J36: 3000 | K36: 46134 | L36: 46154 | M36: Requested demo
A37: ALM-0038 | B37: Fernando Romero | C37: fernando.romero63@gmail.com | D37: 5161885601 | E37: Apex Labs | F37: Colombia | G37: LinkedIn | H37: Data Automation | I37: Proposal Sent | J37: 350 | K37: 46153 | L37: 46161 | M37: Send proposal
A38: ALM-0039 | B38: Fernando Rivera | C38: fernando.rivera80@company.com | D38: +57 1778362014 | F38: Colombia | G38: Instagram | H38: Workflow Automation | I38: Won | J38: 350 | K38: 46090 | L38: 46090 | M38: Interested in automation
A39: ALM-0040 | B39: Isabel Ortiz | C39: isabel.ortiz36@mail.com | D39: +51 652057098 | E39: Momentum Works | F39: Peru | G39: Website | H39: Workflow Automation | I39: Won | J39: 2000 | K39: 46068 | L39: 46107 | M39: Needs pricing
A40: ALM-0041 | B40: Lucía Sánchez | C40: lucia.sanchez5@outlook.com | D40: +503 311 113 05 | E40: Cloud Labs | F40: El Salvador | G40: Facebook | H40: Workflow Automation | I40: Proposal Sent | J40: 350 | K40: 46116 | M40: Needs pricing
...

Sheet REPORT
B2: Client & Lead Data Report
B3: Portfolio Sample — Synthetic Client & Lead Data Report
C6: Total Clean Records | D6: =COUNTA(FINAL_DATA!A2:A1001) -> 191 | G6: Data Quality Summary
C7: Total Estimated Value | D7: =SUM(FINAL_DATA!J2:J192) -> 311450 | G7: Original Records | H7: 200
C8: Average Estimated Value | D8: =AVERAGE(FINAL_DATA!J2:J192) -> 1739.9441 | G8: Duplicates Removed | H8: 9
C9: Records Missing Estimated Value | D9: =COUNTBLANK(FINAL_DATA!J2:J192) -> 12 | G9: Final Clean Records | H9: 191
C10: Records Missing Lead Status | D10: =COUNTBLANK(FINAL_DATA!I2:I192) -> 4 | G10: Duplicate Removal Rate | H10: 0.045
G11: Emails Auto-Fixed | H11: 4
G12: Emails Requiring Review | H12: 4
G13: Missing Emails in Final Dataset | H13: 7
B17: Lead Status | C17: Record Count | E17: Lead Source | F17: Record Count | H17: Service Interest | I17: Record Count
B18: =IFERROR(__xludf.DUMMYFUNCTION("QUERY(FINAL_DATA!I2:I192,""select Col1, count(Col1) where Col1 is not null group by Col1 label Col1 '', count(Col1) ''"",0)"),"Contacted") -> Contacted | C18: =IFERROR(__xludf.DUMMYFUNCTION("""COMPUTED_VALUE"""),26.0) -> 26 | E18: =IFERROR(__xludf.DUMMYFUNCTION("QUERY(FINAL_DATA!G2:G192,""select Col1, count(Col1) where Col1 is not null group by Col1 label Col1 '', count(Col1) ''"",0)"),"Facebook") -> Facebook | F18: =IFERROR(__xludf.DUMMYFUNCTION("""COMPUTED_VALUE"""),30.0) -> 30 | H18: =IFERROR(__xludf.DUMMYFUNCTION("QUERY(FINAL_DATA!H2:H192,""select Col1, count(Col1) where Col1 is not null group by Col1 label Col1 '', count(Col1) ''"",0)"),"AI Voice Agent") -> AI Voice Agent | I18: =IFERROR(__xludf.DUMMYFUNCTION("""COMPUTED_VALUE"""),37.0) -> 37
B19: =IFERROR(__xludf.DUMMYFUNCTION("""COMPUTED_VALUE"""),"Lost") -> Lost | C19: =IFERROR(__xludf.DUMMYFUNCTION("""COMPUTED_VALUE"""),31.0) -> 31 | E19: =IFERROR(__xludf.DUMMYFUNCTION("""COMPUTED_VALUE"""),"Instagram") -> Instagram | F19: =IFERROR(__xludf.DUMMYFUNCTION("""COMPUTED_VALUE"""),27.0) -> 27 | H19: =IFERROR(__xludf.DUMMYFUNCTION("""COMPUTED_VALUE"""),"Data Automation") -> Data Automation | I19: =IFERROR(__xludf.DUMMYFUNCTION("""COMPUTED_VALUE"""),39.0) -> 39
B20: =IFERROR(__xludf.DUMMYFUNCTION("""COMPUTED_VALUE"""),"New") -> New | C20: =IFERROR(__xludf.DUMMYFUNCTION("""COMPUTED_VALUE"""),23.0) -> 23 | E20: =IFERROR(__xludf.DUMMYFUNCTION("""COMPUTED_VALUE"""),"LinkedIn") -> LinkedIn | F20: =IFERROR(__xludf.DUMMYFUNCTION("""COMPUTED_VALUE"""),31.0) -> 31 | H20: =IFERROR(__xludf.DUMMYFUNCTION("""COMPUTED_VALUE"""),"Document Processing") -> Document Processing | I20: =IFERROR(__xludf.DUMMYFUNCTION("""COMPUTED_VALUE"""),41.0) -> 41
B21: =IFERROR(__xludf.DUMMYFUNCTION("""COMPUTED_VALUE"""),"Proposal") -> Proposal | C21: =IFERROR(__xludf.DUMMYFUNCTION("""COMPUTED_VALUE"""),2.0) -> 2 | E21: =IFERROR(__xludf.DUMMYFUNCTION("""COMPUTED_VALUE"""),"Organic Search") -> Organic Search | F21: =IFERROR(__xludf.DUMMYFUNCTION("""COMPUTED_VALUE"""),36.0) -> 36 | H21: =IFERROR(__xludf.DUMMYFUNCTION("""COMPUTED_VALUE"""),"Website Chat Agent") -> Website Chat Agent | I21: =IFERROR(__xludf.DUMMYFUNCTION("""COMPUTED_VALUE"""),31.0) -> 31
B22: =IFERROR(__xludf.DUMMYFUNCTION("""COMPUTED_VALUE"""),"Proposal Sent") -> Proposal Sent | C22: =IFERROR(__xludf.DUMMYFUNCTION("""COMPUTED_VALUE"""),41.0) -> 41 | E22: =IFERROR(__xludf.DUMMYFUNCTION("""COMPUTED_VALUE"""),"Referral") -> Referral | F22: =IFERROR(__xludf.DUMMYFUNCTION("""COMPUTED_VALUE"""),25.0) -> 25 | H22: =IFERROR(__xludf.DUMMYFUNCTION("""COMPUTED_VALUE"""),"Workflow Automation") -> Workflow Automation | I22: =IFERROR(__xludf.DUMMYFUNCTION("""COMPUTED_VALUE"""),43.0) -> 43
B23: =IFERROR(__xludf.DUMMYFUNCTION("""COMPUTED_VALUE"""),"Qualified") -> Qualified | C23: =IFERROR(__xludf.DUMMYFUNCTION("""COMPUTED_VALUE"""),35.0) -> 35 | E23: =IFERROR(__xludf.DUMMYFUNCTION("""COMPUTED_VALUE"""),"Website") -> Website | F23: =IFERROR(__xludf.DUMMYFUNCTION("""COMPUTED_VALUE"""),42.0) -> 42
B24: =IFERROR(__xludf.DUMMYFUNCTION("""COMPUTED_VALUE"""),"Won") -> Won | C24: =IFERROR(__xludf.DUMMYFUNCTION("""COMPUTED_VALUE"""),29.0) -> 29

Sheet README
A1: AI Lab Mind — Data Cleaning Portfolio Exercise
A2: Portfolio Sample — Synthetic Client & Lead Data Report
A4: Section | B4: Content
A5: Purpose | B5: Synthetic client/lead database for a portfolio exercise. No real client data is included.
A6: Scenario | B6: AI Lab Mind exported records from multiple sources. Intentional data-quality problems are present.
A7: Your task | B7: Keep RAW_DATA unchanged. Later we will create a separate cleaned dataset and document each transformation.
A8: Issues included | B8: Duplicates, missing values, inconsistent capitalization/spacing, country variants, inconsistent statuses, malformed/missing emails, phone-format differences and missing dates.
A9: Target skills | B9: Excel / Google Sheets, duplicate detection, formulas, filters, sorting, data cleaning, consolidation and basic reporting.
A10: Portfolio rule | B10: Present this clearly as a sample/synthetic project, not as real customer work.
A12: Dataset size | B12: 200 records + header
A14: Work Performed | B14: Preserved the original raw dataset and created a separate working copy for cleaning, validation, and audit tracking.
