Workbook

Sheet README
A1: Case 02 — Data Consolidation & Reporting
A3: Portfolio Sample | B3: Synthetic business data — not real client work.
A4: Scenario | B4: Commercial information is distributed across separate client, lead, activity, and target files.
A5: Objective | B5: Consolidate the sources into a reliable master dataset and create a management report.
A6: Source 1 | B6: CLIENTS — customer master data.
A7: Source 2 | B7: LEADS — lead, channel, service, owner, status and estimated value.
A8: Source 3 | B8: ACTIVITIES — commercial follow-up activity.
A9: Source 4 | B9: TARGETS — monthly estimated-value targets by owner.
A10: Deliverable | B10: MASTER_DATA + REPORT with KPIs and visual summaries.
A11: Skills Demonstrated | B11: Data consolidation, lookups, COUNTIFS, SUMIFS, date logic, reporting and visualization.
A12: Portfolio Note | B12: This workbook is a synthetic portfolio exercise created to demonstrate workflow and spreadsheet skills.

Sheet CLIENTS
A1: Client_ID | B1: Client_Name | C1: Country | D1: Segment | E1: Client_Since
A2: CLI-001 | B2: Client 001 | C2: El Salvador | D2: Professional Services | E2: 46030
A3: CLI-002 | B3: Client 002 | C3: United States | D3: E-commerce | E3: 46037
A4: CLI-003 | B4: Client 003 | C4: Colombia | D4: Hospitality | E4: 46044
A5: CLI-004 | B5: Client 004 | C5: Mexico | D5: SMB | E5: 46051
A6: CLI-005 | B6: Client 005 | C6: Spain | D6: Professional Services | E6: 46058
A7: CLI-006 | B7: Client 006 | C7: El Salvador | D7: E-commerce | E7: 46065
A8: CLI-007 | B8: Client 007 | C8: United States | D8: Hospitality | E8: 46072
A9: CLI-008 | B9: Client 008 | C9: Colombia | D9: SMB | E9: 46079
A10: CLI-009 | B10: Client 009 | C10: Mexico | D10: Professional Services | E10: 46086
A11: CLI-010 | B11: Client 010 | C11: Spain | D11: E-commerce | E11: 46093
A12: CLI-011 | B12: Client 011 | C12: El Salvador | D12: Hospitality | E12: 46100
A13: CLI-012 | B13: Client 012 | C13: United States | D13: SMB | E13: 46107
... A91: CLI-090 | B91: Client 090 | C91: Spain | D91: E-commerce | E91: 46213

Sheet LEADS
A1: Lead_ID | B1: Client_ID | C1: Created_Date | D1: Lead_Source | E1: Service_Interest | F1: Owner | G1: Lead_Status | H1: Estimated_Value_USD
A2: LEAD-001 | B2: CLI-008 | C2: 46032 | D2: LinkedIn | E2: Website Chat Agent | F2: Alex | G2: Qualified | H2: 787
A3: LEAD-002 | B3: CLI-015 | C3: 46041 | D3: Website | E3: Data Automation | F3: Marta | G3: Proposal Sent | H3: 924
A4: LEAD-003 | B4: CLI-022 | C4: 46050 | D4: Facebook | E4: Workflow Automation | F4: Daniel | G4: Won | H4: 1061
A5: LEAD-004 | B5: CLI-029 | C5: 46059 | D5: Instagram | E5: AI Voice Agent | F5: Sofia | G5: Lost | H5: 0
A6: LEAD-005 | B6: CLI-036 | C6: 46068 | D6: Organic Search | E6: Document Processing | F6: Alex | G6: New | H6: 1335
A7: LEAD-006 | C7: 46077 | D7: Referral | E7: Website Chat Agent | F7: Marta | G7: Qualified | H7: 1472
A8: LEAD-007 | B8: CLI-050 | C8: 46086 | D8: LinkedIn | E8: Data Automation | F8: Daniel | G8: Proposal Sent | H8: 1609
A9: LEAD-008 | B9: CLI-057 | C9: 46095 | D9: Website | E9: Workflow Automation | F9: Sofia | G9: Won | H9: 1746
A10: LEAD-009 | B10: CLI-064 | C10: 46104 | D10: Facebook | E10: AI Voice Agent | F10: Alex | G10: Lost | H10: 0
A11: LEAD-010 | B11: CLI-071 | C11: 46113 | D11: Instagram | E11: Document Processing | F11: Marta | G11: New | H11: 2020
A12: LEAD-011 | B12: CLI-078 | C12: 46122 | D12: Organic Search | E12: Website Chat Agent | F12: Daniel | G12: Qualified | H12: 2157
A13: LEAD-012 | C13: 46131 | D13: Referral | E13: Data Automation | F13: Sofia | G13: Proposal Sent | H13: 2294
A14: LEAD-013 | B14: CLI-002 | C14: 46140 | D14: LinkedIn | E14: Workflow Automation | F14: Alex | G14: Won | H14: 2431
A15: LEAD-014 | B15: CLI-009 | C15: 46149 | D15: Website | E15: AI Voice Agent | F15: Marta | G15: Lost | H15: 0
A16: LEAD-015 | B16: CLI-016 | C16: 46158 | D16: Facebook | E16: Document Processing | F16: Daniel | G16: New | H16: 2705
A17: LEAD-016 | B17: CLI-023 | C17: 46167 | D17: Instagram | E17: Website Chat Agent | F17: Sofia | G17: Qualified | H17: 2842
A18: LEAD-017 | B18: CLI-030 | C18: 46176 | D18: Organic Search | E18: Data Automation | F18: Alex | G18: Proposal Sent | H18: 2979
A19: LEAD-018 | C19: 46185 | D19: Referral | E19: Workflow Automation | F19: Marta | G19: Won | H19: 3116
A20: LEAD-019 | B20: CLI-044 | C20: 46194 | D20: LinkedIn | E20: AI Voice Agent | F20: Daniel | G20: Lost | H20: 0
A21: LEAD-020 | B21: CLI-051 | C21: 46203 | D21: Website | E21: Document Processing | F21: Sofia | G21: New | H21: 3390
A22: LEAD-021 | B22: CLI-058 | C22: 46212 | D22: Facebook | E22: Website Chat Agent | F22: Alex | G22: Qualified | H22: 3527
A23: LEAD-022 | B23: CLI-065 | C23: 46221 | D23: Instagram | E23: Data Automation | F23: Marta | G23: Proposal Sent | H23: 3664
A24: LEAD-023 | B24: CLI-072 | C24: 46230 | D24: Organic Search | E24: Workflow Automation | F24: Daniel | G24: Won | H24: 3801
A25: LEAD-024 | C25: 46239 | D25: Referral | E25: AI Voice Agent | F25: Sofia | G25: Lost | H25: 0
A26: LEAD-025 | B26: CLI-086 | C26: 46248 | D26: LinkedIn | E26: Document Processing | F26: Alex | G26: New | H26: 4075
A27: LEAD-026 | B27: CLI-003 | C27: 46257 | D27: Website | E27: Website Chat Agent | F27: Marta | G27: Qualified | H27: 4212
A28: LEAD-027 | B28: CLI-010 | C28: 46026 | D28: Facebook | E28: Data Automation | F28: Daniel | G28: Proposal Sent | H28: 4349
A29: LEAD-028 | B29: CLI-017 | C29: 46035 | D29: Instagram | E29: Workflow Automation | F29: Sofia | G29: Won | H29: 4486
A30: LEAD-029 | B30: CLI-024 | C30: 46044 | D30: Organic Search | E30: AI Voice Agent | F30: Alex | G30: Lost | H30: 0
A31: LEAD-030 | C31: 46053 | D31: Referral | E31: Document Processing | F31: Marta | G31: New | H31: 4760
A32: LEAD-031 | B32: CLI-038 | C32: 46062 | D32: LinkedIn | E32: Website Chat Agent | F32: Daniel | G32: Qualified | H32: 4897
A33: LEAD-032 | B33: CLI-045 | C33: 46071 | D33: Website | E33: Data Automation | F33: Sofia | G33: Proposal Sent | H33: 5034
A34: LEAD-033 | B34: CLI-052 | C34: 46080 | D34: Facebook | E34: Workflow Automation | F34: Alex | G34: Won | H34: 5171
A35: LEAD-034 | B35: CLI-059 | C35: 46089 | D35: Instagram | E35: AI Voice Agent | F35: Marta | G35: Lost | H35: 0
A36: LEAD-035 | B36: CLI-066 | C36: 46098 | D36: Organic Search | E36: Document Processing | F36: Daniel | G36: New | H36: 845
A37: LEAD-036 | C37: 46107 | D37: Referral | E37: Website Chat Agent | F37: Sofia | G37: Qualified | H37: 982
A38: LEAD-037 | B38: CLI-080 | C38: 46116 | D38: LinkedIn | E38: Data Automation | F38: Alex | G38: Proposal Sent | H38: 1119
A39: LEAD-038 | B39: CLI-087 | C39: 46125 | D39: Website | E39: Workflow Automation | F39: Marta | G39: Won | H39: 1256
A40: LEAD-039 | B40: CLI-004 | C40: 46134 | D40: Facebook | E40: AI Voice Agent | F40: Daniel | G40: Lost | H40: 0
...

Sheet ACTIVITIES
A1: Activity_ID | B1: Lead_ID | C1: Activity_Date | D1: Activity_Type | E1: Owner
A2: ACT-001 | B2: LEAD-014 | C2: 46058 | D2: Meeting | E2: Alex
A3: ACT-002 | B3: LEAD-027 | C3: 46063 | D3: Proposal | E3: Marta
A4: ACT-003 | B4: LEAD-040 | C4: 46068 | D4: Follow-up | E4: Daniel
A5: ACT-004 | B5: LEAD-053 | C5: 46073 | D5: Email | E5: Sofia
A6: ACT-005 | B6: LEAD-066 | C6: 46078 | D6: Meeting | E6: Alex
A7: ACT-006 | B7: LEAD-079 | C7: 46083 | D7: Proposal | E7: Marta
A8: ACT-007 | B8: LEAD-092 | C8: 46088 | D8: Follow-up | E8: Daniel
A9: ACT-008 | B9: LEAD-105 | C9: 46093 | D9: Email | E9: Sofia
A10: ACT-009 | B10: LEAD-118 | C10: 46098 | D10: Meeting | E10: Alex
A11: ACT-010 | B11: LEAD-131 | C11: 46103 | D11: Proposal | E11: Marta
A12: ACT-011 | B12: LEAD-144 | C12: 46108 | D12: Follow-up | E12: Daniel
A13: ACT-012 | B13: LEAD-157 | C13: 46113 | D13: Email | E13: Sofia
... A241: ACT-240 | B241: LEAD-081 | C241: 46028 | D241: Email | E241: Sofia

Sheet TARGETS
A1: Month | B1: Owner | C1: Target_Value_USD
A2: 46023 | B2: Sofia | C2: 15600
A3: 46023 | B3: Daniel | C3: 16100
A4: 46023 | B4: Marta | C4: 15600
A5: 46023 | B5: Alex | C5: 15100
A6: 46054 | B6: Sofia | C6: 16700
A7: 46054 | B7: Daniel | C7: 17200
A8: 46054 | B8: Marta | C8: 16700
A9: 46054 | B9: Alex | C9: 16200
A10: 46082 | B10: Sofia | C10: 17800
A11: 46082 | B11: Daniel | C11: 18300
A12: 46082 | B12: Marta | C12: 17800
A13: 46082 | B13: Alex | C13: 17300
... A33: 46235 | B33: Alex | C33: 15800

Sheet MASTER_DATA
A1: Lead_ID | B1: Client_ID | C1: Client_Name | D1: Country | E1: Segment | F1: Created_Date | G1: Month | H1: Lead_Source | I1: Service_Interest | J1: Owner | K1: Lead_Status | L1: Estimated_Value_USD | M1: Activity_Count | N1: Last_Activity_Date
A2: LEAD-001 | B2: CLI-008 | C2: =IFERROR(VLOOKUP(B2,CLIENTS!$A$2:$E$91,2,FALSE),"Unassigned") -> Client 008 | D2: =IFERROR(VLOOKUP(B2,CLIENTS!$A$2:$E$91,3,FALSE),"Unassigned") -> Colombia | E2: =IFERROR(VLOOKUP(B2,CLIENTS!$A$2:$E$91,4,FALSE),"Unassigned") -> SMB | F2: 46032 | G2: 46023 | H2: LinkedIn | I2: Website Chat Agent | J2: Alex | K2: Qualified | L2: 787 | M2: =COUNTIF(ACTIVITIES!$B$2:$B$241,A2) -> 1 | N2: =IF(M2=0,"",MAXIFS(ACTIVITIES!$C$2:$C$241,ACTIVITIES!$B$2:$B$241,A2)) -> 46118
A3: LEAD-002 | B3: CLI-015 | C3: =IFERROR(VLOOKUP(B3,CLIENTS!$A$2:$E$91,2,FALSE),"Unassigned") -> Client 015 | D3: =IFERROR(VLOOKUP(B3,CLIENTS!$A$2:$E$91,3,FALSE),"Unassigned") -> Spain | E3: =IFERROR(VLOOKUP(B3,CLIENTS!$A$2:$E$91,4,FALSE),"Unassigned") -> Hospitality | F3: 46041 | G3: 46023 | H3: Website | I3: Data Automation | J3: Marta | K3: Proposal Sent | L3: 924 | M3: =COUNTIF(ACTIVITIES!$B$2:$B$241,A3) -> 2 | N3: =IF(M3=0,"",MAXIFS(ACTIVITIES!$C$2:$C$241,ACTIVITIES!$B$2:$B$241,A3)) -> 46238
A4: LEAD-003 | B4: CLI-022 | C4: =IFERROR(VLOOKUP(B4,CLIENTS!$A$2:$E$91,2,FALSE),"Unassigned") -> Client 022 | D4: =IFERROR(VLOOKUP(B4,CLIENTS!$A$2:$E$91,3,FALSE),"Unassigned") -> United States | E4: =IFERROR(VLOOKUP(B4,CLIENTS!$A$2:$E$91,4,FALSE),"Unassigned") -> E-commerce | F4: 46050 | G4: 46023 | H4: Facebook | I4: Workflow Automation | J4: Daniel | K4: Won | L4: 1061 | M4: =COUNTIF(ACTIVITIES!$B$2:$B$241,A4) -> 2 | N4: =IF(M4=0,"",MAXIFS(ACTIVITIES!$C$2:$C$241,ACTIVITIES!$B$2:$B$241,A4)) -> 46243
A5: LEAD-004 | B5: CLI-029 | C5: =IFERROR(VLOOKUP(B5,CLIENTS!$A$2:$E$91,2,FALSE),"Unassigned") -> Client 029 | D5: =IFERROR(VLOOKUP(B5,CLIENTS!$A$2:$E$91,3,FALSE),"Unassigned") -> Mexico | E5: =IFERROR(VLOOKUP(B5,CLIENTS!$A$2:$E$91,4,FALSE),"Unassigned") -> Professional Services | F5: 46059 | G5: 46054 | H5: Instagram | I5: AI Voice Agent | J5: Sofia | K5: Lost | L5: 0 | M5: =COUNTIF(ACTIVITIES!$B$2:$B$241,A5) -> 1 | N5: =IF(M5=0,"",MAXIFS(ACTIVITIES!$C$2:$C$241,ACTIVITIES!$B$2:$B$241,A5)) -> 46118
A6: LEAD-005 | B6: CLI-036 | C6: =IFERROR(VLOOKUP(B6,CLIENTS!$A$2:$E$91,2,FALSE),"Unassigned") -> Client 036 | D6: =IFERROR(VLOOKUP(B6,CLIENTS!$A$2:$E$91,3,FALSE),"Unassigned") -> El Salvador | E6: =IFERROR(VLOOKUP(B6,CLIENTS!$A$2:$E$91,4,FALSE),"Unassigned") -> SMB | F6: 46068 | G6: 46054 | H6: Organic Search | I6: Document Processing | J6: Alex | K6: New | L6: 1335 | M6: =COUNTIF(ACTIVITIES!$B$2:$B$241,A6) -> 1 | N6: =IF(M6=0,"",MAXIFS(ACTIVITIES!$C$2:$C$241,ACTIVITIES!$B$2:$B$241,A6)) -> 46058
A7: LEAD-006 | C7: =IFERROR(VLOOKUP(B7,CLIENTS!$A$2:$E$91,2,FALSE),"Unassigned") -> Unassigned | D7: =IFERROR(VLOOKUP(B7,CLIENTS!$A$2:$E$91,3,FALSE),"Unassigned") -> Unassigned | E7: =IFERROR(VLOOKUP(B7,CLIENTS!$A$2:$E$91,4,FALSE),"Unassigned") -> Unassigned | F7: 46077 | G7: 46054 | H7: Referral | I7: Website Chat Agent | J7: Marta | K7: Qualified | L7: 1472 | M7: =COUNTIF(ACTIVITIES!$B$2:$B$241,A7) -> 2 | N7: =IF(M7=0,"",MAXIFS(ACTIVITIES!$C$2:$C$241,ACTIVITIES!$B$2:$B$241,A7)) -> 46243
A8: LEAD-007 | B8: CLI-050 | C8: =IFERROR(VLOOKUP(B8,CLIENTS!$A$2:$E$91,2,FALSE),"Unassigned") -> Client 050 | D8: =IFERROR(VLOOKUP(B8,CLIENTS!$A$2:$E$91,3,FALSE),"Unassigned") -> Spain | E8: =IFERROR(VLOOKUP(B8,CLIENTS!$A$2:$E$91,4,FALSE),"Unassigned") -> E-commerce | F8: 46086 | G8: 46082 | H8: LinkedIn | I8: Data Automation | J8: Daniel | K8: Proposal Sent | L8: 1609 | M8: =COUNTIF(ACTIVITIES!$B$2:$B$241,A8) -> 2 | N8: =IF(M8=0,"",MAXIFS(ACTIVITIES!$C$2:$C$241,ACTIVITIES!$B$2:$B$241,A8)) -> 46183
A9: LEAD-008 | B9: CLI-057 | C9: =IFERROR(VLOOKUP(B9,CLIENTS!$A$2:$E$91,2,FALSE),"Unassigned") -> Client 057 | D9: =IFERROR(VLOOKUP(B9,CLIENTS!$A$2:$E$91,3,FALSE),"Unassigned") -> United States | E9: =IFERROR(VLOOKUP(B9,CLIENTS!$A$2:$E$91,4,FALSE),"Unassigned") -> Professional Services | F9: 46095 | G9: 46082 | H9: Website | I9: Workflow Automation | J9: Sofia | K9: Won | L9: 1746 | M9: =COUNTIF(ACTIVITIES!$B$2:$B$241,A9) -> 1 | N9: =IF(M9=0,"",MAXIFS(ACTIVITIES!$C$2:$C$241,ACTIVITIES!$B$2:$B$241,A9)) -> 46058
A10: LEAD-009 | B10: CLI-064 | C10: =IFERROR(VLOOKUP(B10,CLIENTS!$A$2:$E$91,2,FALSE),"Unassigned") -> Client 064 | D10: =IFERROR(VLOOKUP(B10,CLIENTS!$A$2:$E$91,3,FALSE),"Unassigned") -> Mexico | E10: =IFERROR(VLOOKUP(B10,CLIENTS!$A$2:$E$91,4,FALSE),"Unassigned") -> SMB | F10: 46104 | G10: 46082 | H10: Facebook | I10: AI Voice Agent | J10: Alex | K10: Lost | L10: 0 | M10: =COUNTIF(ACTIVITIES!$B$2:$B$241,A10) -> 1 | N10: =IF(M10=0,"",MAXIFS(ACTIVITIES!$C$2:$C$241,ACTIVITIES!$B$2:$B$241,A10)) -> 46243
A11: LEAD-010 | B11: CLI-071 | C11: =IFERROR(VLOOKUP(B11,CLIENTS!$A$2:$E$91,2,FALSE),"Unassigned") -> Client 071 | D11: =IFERROR(VLOOKUP(B11,CLIENTS!$A$2:$E$91,3,FALSE),"Unassigned") -> El Salvador | E11: =IFERROR(VLOOKUP(B11,CLIENTS!$A$2:$E$91,4,FALSE),"Unassigned") -> Hospitality | F11: 46113 | G11: 46113 | H11: Instagram | I11: Document Processing | J11: Marta | K11: New | L11: 2020 | M11: =COUNTIF(ACTIVITIES!$B$2:$B$241,A11) -> 2 | N11: =IF(M11=0,"",MAXIFS(ACTIVITIES!$C$2:$C$241,ACTIVITIES!$B$2:$B$241,A11)) -> 46183
A12: LEAD-011 | B12: CLI-078 | C12: =IFERROR(VLOOKUP(B12,CLIENTS!$A$2:$E$91,2,FALSE),"Unassigned") -> Client 078 | D12: =IFERROR(VLOOKUP(B12,CLIENTS!$A$2:$E$91,3,FALSE),"Unassigned") -> Colombia | E12: =IFERROR(VLOOKUP(B12,CLIENTS!$A$2:$E$91,4,FALSE),"Unassigned") -> E-commerce | F12: 46122 | G12: 46113 | H12: Organic Search | I12: Website Chat Agent | J12: Daniel | K12: Qualified | L12: 2157 | M12: =COUNTIF(ACTIVITIES!$B$2:$B$241,A12) -> 2 | N12: =IF(M12=0,"",MAXIFS(ACTIVITIES!$C$2:$C$241,ACTIVITIES!$B$2:$B$241,A12)) -> 46123
A13: LEAD-012 | C13: =IFERROR(VLOOKUP(B13,CLIENTS!$A$2:$E$91,2,FALSE),"Unassigned") -> Unassigned | D13: =IFERROR(VLOOKUP(B13,CLIENTS!$A$2:$E$91,3,FALSE),"Unassigned") -> Unassigned | E13: =IFERROR(VLOOKUP(B13,CLIENTS!$A$2:$E$91,4,FALSE),"Unassigned") -> Unassigned | F13: 46131 | G13: 46113 | H13: Referral | I13: Data Automation | J13: Sofia | K13: Proposal Sent | L13: 2294 | M13: =COUNTIF(ACTIVITIES!$B$2:$B$241,A13) -> 1 | N13: =IF(M13=0,"",MAXIFS(ACTIVITIES!$C$2:$C$241,ACTIVITIES!$B$2:$B$241,A13)) -> 46243
A14: LEAD-013 | B14: CLI-002 | C14: =IFERROR(VLOOKUP(B14,CLIENTS!$A$2:$E$91,2,FALSE),"Unassigned") -> Client 002 | D14: =IFERROR(VLOOKUP(B14,CLIENTS!$A$2:$E$91,3,FALSE),"Unassigned") -> United States | E14: =IFERROR(VLOOKUP(B14,CLIENTS!$A$2:$E$91,4,FALSE),"Unassigned") -> E-commerce | F14: 46140 | G14: 46113 | H14: LinkedIn | I14: Workflow Automation | J14: Alex | K14: Won | L14: 2431 | M14: =COUNTIF(ACTIVITIES!$B$2:$B$241,A14) -> 1 | N14: =IF(M14=0,"",MAXIFS(ACTIVITIES!$C$2:$C$241,ACTIVITIES!$B$2:$B$241,A14)) -> 46183
A15: LEAD-014 | B15: CLI-009 | C15: =IFERROR(VLOOKUP(B15,CLIENTS!$A$2:$E$91,2,FALSE),"Unassigned") -> Client 009 | D15: =IFERROR(VLOOKUP(B15,CLIENTS!$A$2:$E$91,3,FALSE),"Unassigned") -> Mexico | E15: =IFERROR(VLOOKUP(B15,CLIENTS!$A$2:$E$91,4,FALSE),"Unassigned") -> Professional Services | F15: 46149 | G15: 46143 | H15: Website | I15: AI Voice Agent | J15: Marta | K15: Lost | L15: 0 | M15: =COUNTIF(ACTIVITIES!$B$2:$B$241,A15) -> 2 | N15: =IF(M15=0,"",MAXIFS(ACTIVITIES!$C$2:$C$241,ACTIVITIES!$B$2:$B$241,A15)) -> 46123
A16: LEAD-015 | B16: CLI-016 | C16: =IFERROR(VLOOKUP(B16,CLIENTS!$A$2:$E$91,2,FALSE),"Unassigned") -> Client 016 | D16: =IFERROR(VLOOKUP(B16,CLIENTS!$A$2:$E$91,3,FALSE),"Unassigned") -> El Salvador | E16: =IFERROR(VLOOKUP(B16,CLIENTS!$A$2:$E$91,4,FALSE),"Unassigned") -> SMB | F16: 46158 | G16: 46143 | H16: Facebook | I16: Document Processing | J16: Daniel | K16: New | L16: 2705 | M16: =COUNTIF(ACTIVITIES!$B$2:$B$241,A16) -> 2 | N16: =IF(M16=0,"",MAXIFS(ACTIVITIES!$C$2:$C$241,ACTIVITIES!$B$2:$B$241,A16)) -> 46243
A17: LEAD-016 | B17: CLI-023 | C17: =IFERROR(VLOOKUP(B17,CLIENTS!$A$2:$E$91,2,FALSE),"Unassigned") -> Client 023 | D17: =IFERROR(VLOOKUP(B17,CLIENTS!$A$2:$E$91,3,FALSE),"Unassigned") -> Colombia | E17: =IFERROR(VLOOKUP(B17,CLIENTS!$A$2:$E$91,4,FALSE),"Unassigned") -> Hospitality | F17: 46167 | G17: 46143 | H17: Instagram | I17: Website Chat Agent | J17: Sofia | K17: Qualified | L17: 2842 | M17: =COUNTIF(ACTIVITIES!$B$2:$B$241,A17) -> 2 | N17: =IF(M17=0,"",MAXIFS(ACTIVITIES!$C$2:$C$241,ACTIVITIES!$B$2:$B$241,A17)) -> 46248
A18: LEAD-017 | B18: CLI-030 | C18: =IFERROR(VLOOKUP(B18,CLIENTS!$A$2:$E$91,2,FALSE),"Unassigned") -> Client 030 | D18: =IFERROR(VLOOKUP(B18,CLIENTS!$A$2:$E$91,3,FALSE),"Unassigned") -> Spain | E18: =IFERROR(VLOOKUP(B18,CLIENTS!$A$2:$E$91,4,FALSE),"Unassigned") -> E-commerce | F18: 46176 | G18: 46174 | H18: Organic Search | I18: Data Automation | J18: Alex | K18: Proposal Sent | L18: 2979 | M18: =COUNTIF(ACTIVITIES!$B$2:$B$241,A18) -> 1 | N18: =IF(M18=0,"",MAXIFS(ACTIVITIES!$C$2:$C$241,ACTIVITIES!$B$2:$B$241,A18)) -> 46123
A19: LEAD-018 | C19: =IFERROR(VLOOKUP(B19,CLIENTS!$A$2:$E$91,2,FALSE),"Unassigned") -> Unassigned | D19: =IFERROR(VLOOKUP(B19,CLIENTS!$A$2:$E$91,3,FALSE),"Unassigned") -> Unassigned | E19: =IFERROR(VLOOKUP(B19,CLIENTS!$A$2:$E$91,4,FALSE),"Unassigned") -> Unassigned | F19: 46185 | G19: 46174 | H19: Referral | I19: Workflow Automation | J19: Marta | K19: Won | L19: 3116 | M19: =COUNTIF(ACTIVITIES!$B$2:$B$241,A19) -> 1 | N19: =IF(M19=0,"",MAXIFS(ACTIVITIES!$C$2:$C$241,ACTIVITIES!$B$2:$B$241,A19)) -> 46063
A20: LEAD-019 | B20: CLI-044 | C20: =IFERROR(VLOOKUP(B20,CLIENTS!$A$2:$E$91,2,FALSE),"Unassigned") -> Client 044 | D20: =IFERROR(VLOOKUP(B20,CLIENTS!$A$2:$E$91,3,FALSE),"Unassigned") -> Mexico | E20: =IFERROR(VLOOKUP(B20,CLIENTS!$A$2:$E$91,4,FALSE),"Unassigned") -> SMB | F20: 46194 | G20: 46174 | H20: LinkedIn | I20: AI Voice Agent | J20: Daniel | K20: Lost | L20: 0 | M20: =COUNTIF(ACTIVITIES!$B$2:$B$241,A20) -> 2 | N20: =IF(M20=0,"",MAXIFS(ACTIVITIES!$C$2:$C$241,ACTIVITIES!$B$2:$B$241,A20)) -> 46248
A21: LEAD-020 | B21: CLI-051 | C21: =IFERROR(VLOOKUP(B21,CLIENTS!$A$2:$E$91,2,FALSE),"Unassigned") -> Client 051 | D21: =IFERROR(VLOOKUP(B21,CLIENTS!$A$2:$E$91,3,FALSE),"Unassigned") -> El Salvador | E21: =IFERROR(VLOOKUP(B21,CLIENTS!$A$2:$E$91,4,FALSE),"Unassigned") -> Hospitality | F21: 46203 | G21: 46174 | H21: Website | I21: Document Processing | J21: Sofia | K21: New | L21: 3390 | M21: =COUNTIF(ACTIVITIES!$B$2:$B$241,A21) -> 2 | N21: =IF(M21=0,"",MAXIFS(ACTIVITIES!$C$2:$C$241,ACTIVITIES!$B$2:$B$241,A21)) -> 46188
A22: LEAD-021 | B22: CLI-058 | C22: =IFERROR(VLOOKUP(B22,CLIENTS!$A$2:$E$91,2,FALSE),"Unassigned") -> Client 058 | D22: =IFERROR(VLOOKUP(B22,CLIENTS!$A$2:$E$91,3,FALSE),"Unassigned") -> Colombia | E22: =IFERROR(VLOOKUP(B22,CLIENTS!$A$2:$E$91,4,FALSE),"Unassigned") -> E-commerce | F22: 46212 | G22: 46204 | H22: Facebook | I22: Website Chat Agent | J22: Alex | K22: Qualified | L22: 3527 | M22: =COUNTIF(ACTIVITIES!$B$2:$B$241,A22) -> 1 | N22: =IF(M22=0,"",MAXIFS(ACTIVITIES!$C$2:$C$241,ACTIVITIES!$B$2:$B$241,A22)) -> 46063
A23: LEAD-022 | B23: CLI-065 | C23: =IFERROR(VLOOKUP(B23,CLIENTS!$A$2:$E$91,2,FALSE),"Unassigned") -> Client 065 | D23: =IFERROR(VLOOKUP(B23,CLIENTS!$A$2:$E$91,3,FALSE),"Unassigned") -> Spain | E23: =IFERROR(VLOOKUP(B23,CLIENTS!$A$2:$E$91,4,FALSE),"Unassigned") -> Professional Services | F23: 46221 | G23: 46204 | H23: Instagram | I23: Data Automation | J23: Marta | K23: Proposal Sent | L23: 3664 | M23: =COUNTIF(ACTIVITIES!$B$2:$B$241,A23) -> 1 | N23: =IF(M23=0,"",MAXIFS(ACTIVITIES!$C$2:$C$241,ACTIVITIES!$B$2:$B$241,A23)) -> 46248
A24: LEAD-023 | B24: CLI-072 | C24: =IFERROR(VLOOKUP(B24,CLIENTS!$A$2:$E$91,2,FALSE),"Unassigned") -> Client 072 | D24: =IFERROR(VLOOKUP(B24,CLIENTS!$A$2:$E$91,3,FALSE),"Unassigned") -> United States | E24: =IFERROR(VLOOKUP(B24,CLIENTS!$A$2:$E$91,4,FALSE),"Unassigned") -> SMB | F24: 46230 | G24: 46204 | H24: Organic Search | I24: Workflow Automation | J24: Daniel | K24: Won | L24: 3801 | M24: =COUNTIF(ACTIVITIES!$B$2:$B$241,A24) -> 2 | N24: =IF(M24=0,"",MAXIFS(ACTIVITIES!$C$2:$C$241,ACTIVITIES!$B$2:$B$241,A24)) -> 46188
A25: LEAD-024 | C25: =IFERROR(VLOOKUP(B25,CLIENTS!$A$2:$E$91,2,FALSE),"Unassigned") -> Unassigned | D25: =IFERROR(VLOOKUP(B25,CLIENTS!$A$2:$E$91,3,FALSE),"Unassigned") -> Unassigned | E25: =IFERROR(VLOOKUP(B25,CLIENTS!$A$2:$E$91,4,FALSE),"Unassigned") -> Unassigned | F25: 46239 | G25: 46235 | H25: Referral | I25: AI Voice Agent | J25: Sofia | K25: Lost | L25: 0 | M25: =COUNTIF(ACTIVITIES!$B$2:$B$241,A25) -> 2 | N25: =IF(M25=0,"",MAXIFS(ACTIVITIES!$C$2:$C$241,ACTIVITIES!$B$2:$B$241,A25)) -> 46128
A26: LEAD-025 | B26: CLI-086 | C26: =IFERROR(VLOOKUP(B26,CLIENTS!$A$2:$E$91,2,FALSE),"Unassigned") -> Client 086 | D26: =IFERROR(VLOOKUP(B26,CLIENTS!$A$2:$E$91,3,FALSE),"Unassigned") -> El Salvador | E26: =IFERROR(VLOOKUP(B26,CLIENTS!$A$2:$E$91,4,FALSE),"Unassigned") -> E-commerce | F26: 46248 | G26: 46235 | H26: LinkedIn | I26: Document Processing | J26: Alex | K26: New | L26: 4075 | M26: =COUNTIF(ACTIVITIES!$B$2:$B$241,A26) -> 1 | N26: =IF(M26=0,"",MAXIFS(ACTIVITIES!$C$2:$C$241,ACTIVITIES!$B$2:$B$241,A26)) -> 46248
A27: LEAD-026 | B27: CLI-003 | C27: =IFERROR(VLOOKUP(B27,CLIENTS!$A$2:$E$91,2,FALSE),"Unassigned") -> Client 003 | D27: =IFERROR(VLOOKUP(B27,CLIENTS!$A$2:$E$91,3,FALSE),"Unassigned") -> Colombia | E27: =IFERROR(VLOOKUP(B27,CLIENTS!$A$2:$E$91,4,FALSE),"Unassigned") -> Hospitality | F27: 46257 | G27: 46235 | H27: Website | I27: Website Chat Agent | J27: Marta | K27: Qualified | L27: 4212 | M27: =COUNTIF(ACTIVITIES!$B$2:$B$241,A27) -> 1 | N27: =IF(M27=0,"",MAXIFS(ACTIVITIES!$C$2:$C$241,ACTIVITIES!$B$2:$B$241,A27)) -> 46188
A28: LEAD-027 | B28: CLI-010 | C28: =IFERROR(VLOOKUP(B28,CLIENTS!$A$2:$E$91,2,FALSE),"Unassigned") -> Client 010 | D28: =IFERROR(VLOOKUP(B28,CLIENTS!$A$2:$E$91,3,FALSE),"Unassigned") -> Spain | E28: =IFERROR(VLOOKUP(B28,CLIENTS!$A$2:$E$91,4,FALSE),"Unassigned") -> E-commerce | F28: 46026 | G28: 46023 | H28: Facebook | I28: Data Automation | J28: Daniel | K28: Proposal Sent | L28: 4349 | M28: =COUNTIF(ACTIVITIES!$B$2:$B$241,A28) -> 2 | N28: =IF(M28=0,"",MAXIFS(ACTIVITIES!$C$2:$C$241,ACTIVITIES!$B$2:$B$241,A28)) -> 46128
A29: LEAD-028 | B29: CLI-017 | C29: =IFERROR(VLOOKUP(B29,CLIENTS!$A$2:$E$91,2,FALSE),"Unassigned") -> Client 017 | D29: =IFERROR(VLOOKUP(B29,CLIENTS!$A$2:$E$91,3,FALSE),"Unassigned") -> United States | E29: =IFERROR(VLOOKUP(B29,CLIENTS!$A$2:$E$91,4,FALSE),"Unassigned") -> Professional Services | F29: 46035 | G29: 46023 | H29: Instagram | I29: Workflow Automation | J29: Sofia | K29: Won | L29: 4486 | M29: =COUNTIF(ACTIVITIES!$B$2:$B$241,A29) -> 2 | N29: =IF(M29=0,"",MAXIFS(ACTIVITIES!$C$2:$C$241,ACTIVITIES!$B$2:$B$241,A29)) -> 46248
A30: LEAD-029 | B30: CLI-024 | C30: =IFERROR(VLOOKUP(B30,CLIENTS!$A$2:$E$91,2,FALSE),"Unassigned") -> Client 024 | D30: =IFERROR(VLOOKUP(B30,CLIENTS!$A$2:$E$91,3,FALSE),"Unassigned") -> Mexico | E30: =IFERROR(VLOOKUP(B30,CLIENTS!$A$2:$E$91,4,FALSE),"Unassigned") -> SMB | F30: 46044 | G30: 46023 | H30: Organic Search | I30: AI Voice Agent | J30: Alex | K30: Lost | L30: 0 | M30: =COUNTIF(ACTIVITIES!$B$2:$B$241,A30) -> 2 | N30: =IF(M30=0,"",MAXIFS(ACTIVITIES!$C$2:$C$241,ACTIVITIES!$B$2:$B$241,A30)) -> 46253
A31: LEAD-030 | C31: =IFERROR(VLOOKUP(B31,CLIENTS!$A$2:$E$91,2,FALSE),"Unassigned") -> Unassigned | D31: =IFERROR(VLOOKUP(B31,CLIENTS!$A$2:$E$91,3,FALSE),"Unassigned") -> Unassigned | E31: =IFERROR(VLOOKUP(B31,CLIENTS!$A$2:$E$91,4,FALSE),"Unassigned") -> Unassigned | F31: 46053 | G31: 46023 | H31: Referral | I31: Document Processing | J31: Marta | K31: New | L31: 4760 | M31: =COUNTIF(ACTIVITIES!$B$2:$B$241,A31) -> 1 | N31: =IF(M31=0,"",MAXIFS(ACTIVITIES!$C$2:$C$241,ACTIVITIES!$B$2:$B$241,A31)) -> 46128
A32: LEAD-031 | B32: CLI-038 | C32: =IFERROR(VLOOKUP(B32,CLIENTS!$A$2:$E$91,2,FALSE),"Unassigned") -> Client 038 | D32: =IFERROR(VLOOKUP(B32,CLIENTS!$A$2:$E$91,3,FALSE),"Unassigned") -> Colombia | E32: =IFERROR(VLOOKUP(B32,CLIENTS!$A$2:$E$91,4,FALSE),"Unassigned") -> E-commerce | F32: 46062 | G32: 46054 | H32: LinkedIn | I32: Website Chat Agent | J32: Daniel | K32: Qualified | L32: 4897 | M32: =COUNTIF(ACTIVITIES!$B$2:$B$241,A32) -> 1 | N32: =IF(M32=0,"",MAXIFS(ACTIVITIES!$C$2:$C$241,ACTIVITIES!$B$2:$B$241,A32)) -> 46068
A33: LEAD-032 | B33: CLI-045 | C33: =IFERROR(VLOOKUP(B33,CLIENTS!$A$2:$E$91,2,FALSE),"Unassigned") -> Client 045 | D33: =IFERROR(VLOOKUP(B33,CLIENTS!$A$2:$E$91,3,FALSE),"Unassigned") -> Spain | E33: =IFERROR(VLOOKUP(B33,CLIENTS!$A$2:$E$91,4,FALSE),"Unassigned") -> Professional Services | F33: 46071 | G33: 46054 | H33: Website | I33: Data Automation | J33: Sofia | K33: Proposal Sent | L33: 5034 | M33: =COUNTIF(ACTIVITIES!$B$2:$B$241,A33) -> 2 | N33: =IF(M33=0,"",MAXIFS(ACTIVITIES!$C$2:$C$241,ACTIVITIES!$B$2:$B$241,A33)) -> 46253
A34: LEAD-033 | B34: CLI-052 | C34: =IFERROR(VLOOKUP(B34,CLIENTS!$A$2:$E$91,2,FALSE),"Unassigned") -> Client 052 | D34: =IFERROR(VLOOKUP(B34,CLIENTS!$A$2:$E$91,3,FALSE),"Unassigned") -> United States | E34: =IFERROR(VLOOKUP(B34,CLIENTS!$A$2:$E$91,4,FALSE),"Unassigned") -> SMB | F34: 46080 | G34: 46054 | H34: Facebook | I34: Workflow Automation | J34: Alex | K34: Won | L34: 5171 | M34: =COUNTIF(ACTIVITIES!$B$2:$B$241,A34) -> 2 | N34: =IF(M34=0,"",MAXIFS(ACTIVITIES!$C$2:$C$241,ACTIVITIES!$B$2:$B$241,A34)) -> 46193
A35: LEAD-034 | B35: CLI-059 | C35: =IFERROR(VLOOKUP(B35,CLIENTS!$A$2:$E$91,2,FALSE),"Unassigned") -> Client 059 | D35: =IFERROR(VLOOKUP(B35,CLIENTS!$A$2:$E$91,3,FALSE),"Unassigned") -> Mexico | E35: =IFERROR(VLOOKUP(B35,CLIENTS!$A$2:$E$91,4,FALSE),"Unassigned") -> Hospitality | F35: 46089 | G35: 46082 | H35: Instagram | I35: AI Voice Agent | J35: Marta | K35: Lost | L35: 0 | M35: =COUNTIF(ACTIVITIES!$B$2:$B$241,A35) -> 1 | N35: =IF(M35=0,"",MAXIFS(ACTIVITIES!$C$2:$C$241,ACTIVITIES!$B$2:$B$241,A35)) -> 46068
A36: LEAD-035 | B36: CLI-066 | C36: =IFERROR(VLOOKUP(B36,CLIENTS!$A$2:$E$91,2,FALSE),"Unassigned") -> Client 066 | D36: =IFERROR(VLOOKUP(B36,CLIENTS!$A$2:$E$91,3,FALSE),"Unassigned") -> El Salvador | E36: =IFERROR(VLOOKUP(B36,CLIENTS!$A$2:$E$91,4,FALSE),"Unassigned") -> E-commerce | F36: 46098 | G36: 46082 | H36: Organic Search | I36: Document Processing | J36: Daniel | K36: New | L36: 845 | M36: =COUNTIF(ACTIVITIES!$B$2:$B$241,A36) -> 1 | N36: =IF(M36=0,"",MAXIFS(ACTIVITIES!$C$2:$C$241,ACTIVITIES!$B$2:$B$241,A36)) -> 46253
A37: LEAD-036 | C37: =IFERROR(VLOOKUP(B37,CLIENTS!$A$2:$E$91,2,FALSE),"Unassigned") -> Unassigned | D37: =IFERROR(VLOOKUP(B37,CLIENTS!$A$2:$E$91,3,FALSE),"Unassigned") -> Unassigned | E37: =IFERROR(VLOOKUP(B37,CLIENTS!$A$2:$E$91,4,FALSE),"Unassigned") -> Unassigned | F37: 46107 | G37: 46082 | H37: Referral | I37: Website Chat Agent | J37: Sofia | K37: Qualified | L37: 982 | M37: =COUNTIF(ACTIVITIES!$B$2:$B$241,A37) -> 2 | N37: =IF(M37=0,"",MAXIFS(ACTIVITIES!$C$2:$C$241,ACTIVITIES!$B$2:$B$241,A37)) -> 46193
A38: LEAD-037 | B38: CLI-080 | C38: =IFERROR(VLOOKUP(B38,CLIENTS!$A$2:$E$91,2,FALSE),"Unassigned") -> Client 080 | D38: =IFERROR(VLOOKUP(B38,CLIENTS!$A$2:$E$91,3,FALSE),"Unassigned") -> Spain | E38: =IFERROR(VLOOKUP(B38,CLIENTS!$A$2:$E$91,4,FALSE),"Unassigned") -> SMB | F38: 46116 | G38: 46113 | H38: LinkedIn | I38: Data Automation | J38: Alex | K38: Proposal Sent | L38: 1119 | M38: =COUNTIF(ACTIVITIES!$B$2:$B$241,A38) -> 2 | N38: =IF(M38=0,"",MAXIFS(ACTIVITIES!$C$2:$C$241,ACTIVITIES!$B$2:$B$241,A38)) -> 46133
A39: LEAD-038 | B39: CLI-087 | C39: =IFERROR(VLOOKUP(B39,CLIENTS!$A$2:$E$91,2,FALSE),"Unassigned") -> Client 087 | D39: =IFERROR(VLOOKUP(B39,CLIENTS!$A$2:$E$91,3,FALSE),"Unassigned") -> United States | E39: =IFERROR(VLOOKUP(B39,CLIENTS!$A$2:$E$91,4,FALSE),"Unassigned") -> Hospitality | F39: 46125 | G39: 46113 | H39: Website | I39: Workflow Automation | J39: Marta | K39: Won | L39: 1256 | M39: =COUNTIF(ACTIVITIES!$B$2:$B$241,A39) -> 1 | N39: =IF(M39=0,"",MAXIFS(ACTIVITIES!$C$2:$C$241,ACTIVITIES!$B$2:$B$241,A39)) -> 46253
A40: LEAD-039 | B40: CLI-004 | C40: =IFERROR(VLOOKUP(B40,CLIENTS!$A$2:$E$91,2,FALSE),"Unassigned") -> Client 004 | D40: =IFERROR(VLOOKUP(B40,CLIENTS!$A$2:$E$91,3,FALSE),"Unassigned") -> Mexico | E40: =IFERROR(VLOOKUP(B40,CLIENTS!$A$2:$E$91,4,FALSE),"Unassigned") -> SMB | F40: 46134 | G40: 46113 | H40: Facebook | I40: AI Voice Agent | J40: Daniel | K40: Lost | L40: 0 | M40: =COUNTIF(ACTIVITIES!$B$2:$B$241,A40) -> 1 | N40: =IF(M40=0,"",MAXIFS(ACTIVITIES!$C$2:$C$241,ACTIVITIES!$B$2:$B$241,A40)) -> 46193
...

Sheet REPORT
A1: Business Consolidation & Performance Report
A2: Portfolio Sample — Synthetic Multi-Source Business Data
A4: Total Leads | C4: Estimated Pipeline | E4: Won Leads | G4: Conversion Rate | I4: Commercial Activities
A5: =COUNTA(MASTER_DATA!A2:A161) -> 160 | C5: =SUM(MASTER_DATA!L2:L161) -> 368064 | E5: =COUNTIF(MASTER_DATA!K2:K161,"Won") -> 32 | G5: =COUNTIF(MASTER_DATA!K2:K161,"Won")/COUNTA(MASTER_DATA!A2:A161) -> 0.2 | I5: =COUNTA(ACTIVITIES!A2:A241) -> 240
A8: Lead Status | B8: Count | D8: Lead Source | E8: Count | G8: Service Interest | H8: Pipeline Value
A9: New | B9: =COUNTIF(MASTER_DATA!$K$2:$K$161,A9) -> 32 | D9: Website | E9: =COUNTIF(MASTER_DATA!$H$2:$H$161,D9) -> 27 | G9: Workflow Automation | H9: =SUMIF(MASTER_DATA!$I$2:$I$161,G9,MASTER_DATA!$L$2:$L$161) -> 93112
A10: Qualified | B10: =COUNTIF(MASTER_DATA!$K$2:$K$161,A10) -> 32 | D10: LinkedIn | E10: =COUNTIF(MASTER_DATA!$H$2:$H$161,D10) -> 27 | G10: Document Processing | H10: =SUMIF(MASTER_DATA!$I$2:$I$161,G10,MASTER_DATA!$L$2:$L$161) -> 92680
A11: Proposal Sent | B11: =COUNTIF(MASTER_DATA!$K$2:$K$161,A11) -> 32 | D11: Referral | E11: =COUNTIF(MASTER_DATA!$H$2:$H$161,D11) -> 26 | G11: Data Automation | H11: =SUMIF(MASTER_DATA!$I$2:$I$161,G11,MASTER_DATA!$L$2:$L$161) -> 93328
A12: Won | B12: =COUNTIF(MASTER_DATA!$K$2:$K$161,A12) -> 32 | D12: Organic Search | E12: =COUNTIF(MASTER_DATA!$H$2:$H$161,D12) -> 26 | G12: AI Voice Agent | H12: =SUMIF(MASTER_DATA!$I$2:$I$161,G12,MASTER_DATA!$L$2:$L$161) -> 0
A13: Lost | B13: =COUNTIF(MASTER_DATA!$K$2:$K$161,A13) -> 32 | D13: Instagram | E13: =COUNTIF(MASTER_DATA!$H$2:$H$161,D13) -> 27 | G13: Website Chat Agent | H13: =SUMIF(MASTER_DATA!$I$2:$I$161,G13,MASTER_DATA!$L$2:$L$161) -> 88944
D14: Facebook | E14: =COUNTIF(MASTER_DATA!$H$2:$H$161,D14) -> 27
A17: Owner | B17: Pipeline Value | C17: Target (Jan-Aug)
A18: Sofia | B18: =SUMIF(MASTER_DATA!$J$2:$J$161,A18,MASTER_DATA!$L$2:$L$161) -> 94656 | C18: =SUMIF(TARGETS!$B$2:$B$33,A18,TARGETS!$C$2:$C$33) -> 127600
A19: Daniel | B19: =SUMIF(MASTER_DATA!$J$2:$J$161,A19,MASTER_DATA!$L$2:$L$161) -> 91136 | C19: =SUMIF(TARGETS!$B$2:$B$33,A19,TARGETS!$C$2:$C$33) -> 124600
A20: Marta | B20: =SUMIF(MASTER_DATA!$J$2:$J$161,A20,MASTER_DATA!$L$2:$L$161) -> 91136 | C20: =SUMIF(TARGETS!$B$2:$B$33,A20,TARGETS!$C$2:$C$33) -> 127600
A21: Alex | B21: =SUMIF(MASTER_DATA!$J$2:$J$161,A21,MASTER_DATA!$L$2:$L$161) -> 91136 | C21: =SUMIF(TARGETS!$B$2:$B$33,A21,TARGETS!$C$2:$C$33) -> 123600

Sheet CASO_02_ES
A1: CASO 02 — Consolidación de Datos y Reporting
A3: TIPO | B3: Proyecto de muestra con datos sintéticos
A4: PROBLEMA | B4: La información comercial estaba distribuida en cuatro fuentes: clientes, leads, actividades y objetivos mensuales.
A5: OBJETIVO | B5: Consolidar las fuentes en una base maestra y convertirlas en un reporte de gestión con KPIs y visualizaciones.
A6: PROCESO | B6: Relacioné las fuentes mediante identificadores, incorporé datos de clientes con búsquedas, resumí actividad comercial, organicé fechas y construí métricas de desempeño.
A7: RESULTADO | B7: Una base MASTER_DATA consolidada y un dashboard que permite analizar pipeline, conversión, fuentes, servicios, actividad y desempeño frente a objetivos.
A8: HERRAMIENTAS | B8: Excel / Google Sheets · VLOOKUP/BUSCARV · COUNTIF/CONTAR.SI · SUMIF/SUMAR.SI · manejo de fechas · tablas · gráficos
A9: EVIDENCIA | B9: Las hojas CLIENTS, LEADS, ACTIVITIES y TARGETS representan los archivos de origen; MASTER_DATA es la consolidación; REPORT es el entregable visual.
